Workbook

Sheet Foglio1
M4: servizi singoli | N4: servizi di gruppo
M6: =GETPIVOTDATA("Ore",$A$4,"Addetto","CROCE MARIA GRAZIA")*27 -> 1296 | O6: croce 120
M8: =GETPIVOTDATA("Ore",$A$4,"Addetto","FALCONE SERENA")*25 -> 9037.5 | N8: =71*35 -> 2485 | O8: falcone 71
M10: =GETPIVOTDATA("Ore",$A$4,"Addetto","LA MANTIA DANILO")*25 -> #REF!
M11: =GETPIVOTDATA("Ore",$A$4,"Addetto","MAINERO CLAUDIA")*25 -> 14475 | N11: =52*35 -> 1820 | O11: mainero 52
M20: =SUM(M6:M19) -> #REF!

Sheet exp_SILP
A1: CF su Proforma | B1: Servizio PROFORMA | C1: COMMESSA | D1: Dalle | E1: Alle | F1: Ore | G1: Codice Fiscale Docente | H1: Codice Voce di Spesa | I1: BackOffice (S,N) | J1: Codice Sede | K1: N | L1: VALORE CM | M1: VALORE COMMESSE | N1: PROGETTO | O1: RICAVI | P1: Sesso (M,F) | Q1: Data | R1: Orario | S1: Servizio | T1: Ambito | U1: Progetto2 | V1: Soggetto | W1: Codice fiscale | X1: Data di nascita | Y1: Addetto | Z1: Esito | AA1: Ente | AB1: Tipologia | AC1: Luogo | AD1: Altro luogo | AE1: Motivazione | AF1: Note | AG1: Durata | AH1: Data esito | AI1: Utente inserimento | AJ1: CF CM
A2: =IFERROR(VLOOKUP(exp_SILP!$W2,exp_utenti_P!D:D,1,FALSE),"_DA INSERIRE") -> BNMKLD71A18Z330T | B2: =IF(AND(exp_SILP!$S2="A.3 ORIENTAMENTO PROFESSIONALE",exp_SILP!$AD2="4.2"),"A.3 ORIENTAMENTO PROFESSIONALE (CARCERE)", IF(AND(exp_SILP!$S2="A.3 ORIENTAMENTO PROFESSIONALE",exp_SILP!$AD2="."),"A.3 ORIENTAMENTO PROFESSIONALE (CARCERE)", IF(AND(exp_SILP!$S2="A.4 CONSULENZA ORIENTATIVA",exp_SILP!$AD2="4.2"),"A.4 CONSULENZA ORIENTATIVA (CARCERE)", IF(AND(exp_SILP!$S2="A.4 CONSULENZA ORIENTATIVA",exp_SILP!$AD2="."),"A.4 CONSULENZA ORIENTATIVA (CARCERE)", IF(AND(exp_SILP!$S2="A.5 - LEP F1 - ACCOMPAGNAMENTO AL LAVORO",exp_SILP!$AD2="4.2"),"A.5 - LEP F1 - ACCOMPAGNAMENTO AL LAVORO (CARCERE)", IF(AND(exp_SILP!$S2="A.5 - LEP F1 - ACCOMPAGNAMENTO AL LAVORO",exp_SILP!$AD2="."),"A.5 - LEP F1 - ACCOMPAGNAMENTO AL LAVORO (CARCERE)", IF(AND(exp_SILP!$S2="A.5.2a - TUTORAGGIO TIROCINI",exp_SILP!$AD2="4.2"),"A.5.2a - TUTORAGGIO TIROCINI (CARCERE)", exp_SILP!$S2))))))) -> A.5 - LEP F1 - ACCOMPAGNAMENTO AL LAVORO | C2: =CONCATENATE(VLOOKUP(exp_SILP!$B2,'DATI COMMESSE'!$A$2:$F$25,4,FALSE)," - ", VLOOKUP(exp_SILP!$B2,'DATI COMMESSE'!$A$2:$F$25,2,FALSE)," - ",VLOOKUP(exp_SILP!$B2,'DATI COMMESSE'!$A$2:$F$25,3,FALSE)) -> GOL - 22-02-5000 - 22-12-5003 | D2: =LEFT(exp_SILP!$R2,5) -> 14:00 | E2: =RIGHT(exp_SILP!$R2,5) -> 15:00 | F2: =IF(exp_SILP!$AG2>=60,exp_SILP!$AG2/60,exp_SILP!$AG2) -> 1 | G2: =VLOOKUP(exp_SILP!$Y2,'DATI CM'!$A$2:$F$28,2,FALSE) -> PNFMRT85H50A859E | H2: =VLOOKUP(exp_SILP!$Y2,'DATI CM'!$A$2:$F$28,3,FALSE) -> A011 | I2: =IF(A2>0,"N","N") -> N | J2: =VLOOKUP(exp_SILP!$Y2,'DATI CM'!$A$2:$F$28,4,FALSE) -> BIELLA | K2: =VLOOKUP(exp_SILP!$B2,'DATI COMMESSE'!$A$2:$F$25,5,FALSE) -> 39.94 | L2: =IF(exp_SILP!$B2="A4.10 - LEP E - ORIENTAMENTO SPECIALISTICO SKILL GAP ANALYSIS - GRUPPO 3P",0,VLOOKUP(exp_SILP!$Y2,'DATI CM'!$A$2:$F$28,6,FALSE)) -> 25 | M2: =IFERROR(VLOOKUP(exp_SILP!$B2,'DATI CM'!$H$2:$I$16,2,FALSE)*exp_SILP!$F2,0) -> 0 | N2: =VLOOKUP(exp_SILP!$B2,'DATI COMMESSE'!$A$2:$F$25,4,FALSE) -> GOL | O2: =VLOOKUP(exp_SILP!$B2,'DATI COMMESSE'!$A$2:$F$25,5,FALSE)*exp_SILP!$F2 -> 39.94 | P2: =IF(MID(exp_SILP!$W2,10,2)>"40","F","M") -> M | Q2: 01/02/2023 | R2: 14:00-15:00 | S2: A.5 - LEP F1 - ACCOMPAGNAMENTO AL LAVORO | T2: Progetti per accreditati | V2: BENAIM KHALID | W2: BNMKLD71A18Z330T | X2: 18/01/1971 | Y2: PIANOFORTE MARTA | Z2: Erogato | AA2: INFORCOOP ECIPA PIEMONTE | AB2: Incontro MDL | AC2: INFORCOOP ECIPA PIEMONTE STRADA CAMPAGNE' 7 - BIELLA | AG2: 60 | AH2: 01/02/2023 | AI2: PNFMRT85H50A859E | AJ2: =VLOOKUP(exp_SILP!$Y2,'DATI CM'!$A$2:$F$28,2,FALSE) -> PNFMRT85H50A859E
A3: =IFERROR(VLOOKUP(exp_SILP!$W3,exp_utenti_P!D:D,1,FALSE),"_DA INSERIRE") -> GLLGLC68P10L219E | B3: =IF(AND(exp_SILP!$S3="A.3 ORIENTAMENTO PROFESSIONALE",exp_SILP!$AD3="4.2"),"A.3 ORIENTAMENTO PROFESSIONALE (CARCERE)", IF(AND(exp_SILP!$S3="A.3 ORIENTAMENTO PROFESSIONALE",exp_SILP!$AD3="."),"A.3 ORIENTAMENTO PROFESSIONALE (CARCERE)", IF(AND(exp_SILP!$S3="A.4 CONSULENZA ORIENTATIVA",exp_SILP!$AD3="4.2"),"A.4 CONSULENZA ORIENTATIVA (CARCERE)", IF(AND(exp_SILP!$S3="A.4 CONSULENZA ORIENTATIVA",exp_SILP!$AD3="."),"A.4 CONSULENZA ORIENTATIVA (CARCERE)", IF(AND(exp_SILP!$S3="A.5 - LEP F1 - ACCOMPAGNAMENTO AL LAVORO",exp_SILP!$AD3="4.2"),"A.5 - LEP F1 - ACCOMPAGNAMENTO AL LAVORO (CARCERE)", IF(AND(exp_SILP!$S3="A.5 - LEP F1 - ACCOMPAGNAMENTO AL LAVORO",exp_SILP!$AD3="."),"A.5 - LEP F1 - ACCOMPAGNAMENTO AL LAVORO (CARCERE)", IF(AND(exp_SILP!$S3="A.5.2a - TUTORAGGIO TIROCINI",exp_SILP!$AD3="4.2"),"A.5.2a - TUTORAGGIO TIROCINI (CARCERE)", exp_SILP!$S3))))))) -> A4.10 - LEP E - ORIENTAMENTO SPECIALISTICO SKILL GAP ANALYSIS | C3: =CONCATENATE(VLOOKUP(exp_SILP!$B3,'DATI COMMESSE'!$A$2:$F$25,4,FALSE)," - ", VLOOKUP(exp_SILP!$B3,'DATI COMMESSE'!$A$2:$F$25,2,FALSE)," - ",VLOOKUP(exp_SILP!$B3,'DATI COMMESSE'!$A$2:$F$25,3,FALSE)) -> GOL - 22-02-5000 - 22-12-5003 | D3: =LEFT(exp_SILP!$R3,5) -> 14:00 | E3: =RIGHT(exp_SILP!$R3,5) -> 16:00 | F3: =IF(exp_SILP!$AG3>=60,exp_SILP!$AG3/60,exp_SILP!$AG3) -> 2 | G3: =VLOOKUP(exp_SILP!$Y3,'DATI CM'!$A$2:$F$28,2,FALSE) -> FLCSRN79S42L219X | H3: =VLOOKUP(exp_SILP!$Y3,'DATI CM'!$A$2:$F$28,3,FALSE) -> A011 | I3: =IF(A3>0,"N","N") -> N | J3: =VLOOKUP(exp_SILP!$Y3,'DATI CM'!$A$2:$F$28,4,FALSE) -> TORINO | K3: =VLOOKUP(exp_SILP!$B3,'DATI COMMESSE'!$A$2:$F$25,5,FALSE) -> 39.94 | L3: =IF(exp_SILP!$B3="A4.10 - LEP E - ORIENTAMENTO SPECIALISTICO SKILL GAP ANALYSIS - GRUPPO 3P",0,VLOOKUP(exp_SILP!$Y3,'DATI CM'!$A$2:$F$28,6,FALSE)) -> 25 | M3: =IFERROR(VLOOKUP(exp_SILP!$B3,'DATI CM'!$H$2:$I$16,2,FALSE)*exp_SILP!$F3,0) -> 0 | N3: =VLOOKUP(exp_SILP!$B3,'DATI COMMESSE'!$A$2:$F$25,4,FALSE) -> GOL | O3: =VLOOKUP(exp_SILP!$B3,'DATI COMMESSE'!$A$2:$F$25,5,FALSE)*exp_SILP!$F3 -> 79.88 | P3: =IF(MID(exp_SILP!$W3,10,2)>"40","F","M") -> M | Q3: 01/02/2023 | R3: 14:00-16:00 | S3: A4.10 - LEP E - ORIENTAMENTO SPECIALISTICO SKILL GAP ANALYSIS | T3: Progetti per accreditati | V3: UGLIOLA GIANLUCA | W3: GLLGLC68P10L219E | X3: 10/09/1968 | Y3: FALCONE SERENA | Z3: Erogato | AA3: INFORCOOP ECIPA PIEMONTE | AB3: Incontro MDLpresentato | AC3: INFORCOOP ECIPA PIEMONTE VIA LIVORNO 53/b - TORINO | AG3: 120 | AH3: 01/02/2023 | AI3: FLCSRN79S42L219X | AJ3: =VLOOKUP(exp_SILP!$Y3,'DATI CM'!$A$2:$F$28,2,FALSE) -> FLCSRN79S42L219X
A4: =IFERROR(VLOOKUP(exp_SILP!$W4,exp_utenti_P!D:D,1,FALSE),"_DA INSERIRE") -> CLMCRN71T70B019R | B4: =IF(AND(exp_SILP!$S4="A.3 ORIENTAMENTO PROFESSIONALE",exp_SILP!$AD4="4.2"),"A.3 ORIENTAMENTO PROFESSIONALE (CARCERE)", IF(AND(exp_SILP!$S4="A.3 ORIENTAMENTO PROFESSIONALE",exp_SILP!$AD4="."),"A.3 ORIENTAMENTO PROFESSIONALE (CARCERE)", IF(AND(exp_SILP!$S4="A.4 CONSULENZA ORIENTATIVA",exp_SILP!$AD4="4.2"),"A.4 CONSULENZA ORIENTATIVA (CARCERE)", IF(AND(exp_SILP!$S4="A.4 CONSULENZA ORIENTATIVA",exp_SILP!$AD4="."),"A.4 CONSULENZA ORIENTATIVA (CARCERE)", IF(AND(exp_SILP!$S4="A.5 - LEP F1 - ACCOMPAGNAMENTO AL LAVORO",exp_SILP!$AD4="4.2"),"A.5 - LEP F1 - ACCOMPAGNAMENTO AL LAVORO (CARCERE)", IF(AND(exp_SILP!$S4="A.5 - LEP F1 - ACCOMPAGNAMENTO AL LAVORO",exp_SILP!$AD4="."),"A.5 - LEP F1 - ACCOMPAGNAMENTO AL LAVORO (CARCERE)", IF(AND(exp_SILP!$S4="A.5.2a - TUTORAGGIO TIROCINI",exp_SILP!$AD4="4.2"),"A.5.2a - TUTORAGGIO TIROCINI (CARCERE)", exp_SILP!$S4))))))) -> A4.10 - LEP E - ORIENTAMENTO SPECIALISTICO SKILL GAP ANALYSIS | C4: =CONCATENATE(VLOOKUP(exp_SILP!$B4,'DATI COMMESSE'!$A$2:$F$25,4,FALSE)," - ", VLOOKUP(exp_SILP!$B4,'DATI COMMESSE'!$A$2:$F$25,2,FALSE)," - ",VLOOKUP(exp_SILP!$B4,'DATI COMMESSE'!$A$2:$F$25,3,FALSE)) -> GOL - 22-02-5000 - 22-12-5003 | D4: =LEFT(exp_SILP!$R4,5) -> 09:30 | E4: =RIGHT(exp_SILP!$R4,5) -> 11:30 | F4: =IF(exp_SILP!$AG4>=60,exp_SILP!$AG4/60,exp_SILP!$AG4) -> 2 | G4: =VLOOKUP(exp_SILP!$Y4,'DATI CM'!$A$2:$F$28,2,FALSE) -> TRZCST69B41F952V | H4: =VLOOKUP(exp_SILP!$Y4,'DATI CM'!$A$2:$F$28,3,FALSE) | I4: =IF(A4>0,"N","N") -> N | J4: =VLOOKUP(exp_SILP!$Y4,'DATI CM'!$A$2:$F$28,4,FALSE) | K4: =VLOOKUP(exp_SILP!$B4,'DATI COMMESSE'!$A$2:$F$25,5,FALSE) -> 39.94 | L4: =IF(exp_SILP!$B4="A4.10 - LEP E - ORIENTAMENTO SPECIALISTICO SKILL GAP ANALYSIS - GRUPPO 3P",0,VLOOKUP(exp_SILP!$Y4,'DATI CM'!$A$2:$F$28,6,FALSE)) | M4: =IFERROR(VLOOKUP(exp_SILP!$B4,'DATI CM'!$H$2:$I$16,2,FALSE)*exp_SILP!$F4,0) -> 0 | N4: =VLOOKUP(exp_SILP!$B4,'DATI COMMESSE'!$A$2:$F$25,4,FALSE) -> GOL | O4: =VLOOKUP(exp_SILP!$B4,'DATI COMMESSE'!$A$2:$F$25,5,FALSE)*exp_SILP!$F4 -> 79.88 | P4: =IF(MID(exp_SILP!$W4,10,2)>"40","F","M") -> F | Q4: 01/02/2023 | R4: 09:30-11:30 | S4: A4.10 - LEP E - ORIENTAMENTO SPECIALISTICO SKILL GAP ANALYSIS | T4: Progetti per accreditati | V4: COLOMBO CATERINA | W4: CLMCRN71T70B019R | X4: 30/12/1971 | Y4: TERZERA CRISTINA | Z4: Erogato | AA4: INFORCOOP ECIPA PIEMONTE | AB4: Incontro MDL | AC4: INFORCOOP ECIPA PIEMONTE VIA UGO PORZIO GIOVANOLA 7 - NOVARA | AG4: 120 | AH4: 01/02/2023 | AI4: TRZCST69B41F952V | AJ4: =VLOOKUP(exp_SILP!$Y4,'DATI CM'!$A$2:$F$28,2,FALSE) -> TRZCST69B41F952V
A5: =IFERROR(VLOOKUP(exp_SILP!$W5,exp_utenti_P!D:D,1,FALSE),"_DA INSERIRE") -> MNTSRH76E27Z138U | B5: =IF(AND(exp_SILP!$S5="A.3 ORIENTAMENTO PROFESSIONALE",exp_SILP!$AD5="4.2"),"A.3 ORIENTAMENTO PROFESSIONALE (CARCERE)", IF(AND(exp_SILP!$S5="A.3 ORIENTAMENTO PROFESSIONALE",exp_SILP!$AD5="."),"A.3 ORIENTAMENTO PROFESSIONALE (CARCERE)", IF(AND(exp_SILP!$S5="A.4 CONSULENZA ORIENTATIVA",exp_SILP!$AD5="4.2"),"A.4 CONSULENZA ORIENTATIVA (CARCERE)", IF(AND(exp_SILP!$S5="A.4 CONSULENZA ORIENTATIVA",exp_SILP!$AD5="."),"A.4 CONSULENZA ORIENTATIVA (CARCERE)", IF(AND(exp_SILP!$S5="A.5 - LEP F1 - ACCOMPAGNAMENTO AL LAVORO",exp_SILP!$AD5="4.2"),"A.5 - LEP F1 - ACCOMPAGNAMENTO AL LAVORO (CARCERE)", IF(AND(exp_SILP!$S5="A.5 - LEP F1 - ACCOMPAGNAMENTO AL LAVORO",exp_SILP!$AD5="."),"A.5 - LEP F1 - ACCOMPAGNAMENTO AL LAVORO (CARCERE)", IF(AND(exp_SILP!$S5="A.5.2a - TUTORAGGIO TIROCINI",exp_SILP!$AD5="4.2"),"A.5.2a - TUTORAGGIO TIROCINI (CARCERE)", exp_SILP!$S5))))))) -> A4.10 - LEP E - ORIENTAMENTO SPECIALISTICO SKILL GAP ANALYSIS | C5: =CONCATENATE(VLOOKUP(exp_SILP!$B5,'DATI COMMESSE'!$A$2:$F$25,4,FALSE)," - ", VLOOKUP(exp_SILP!$B5,'DATI COMMESSE'!$A$2:$F$25,2,FALSE)," - ",VLOOKUP(exp_SILP!$B5,'DATI COMMESSE'!$A$2:$F$25,3,FALSE)) -> GOL - 22-02-5000 - 22-12-5003 | D5: =LEFT(exp_SILP!$R5,5) -> 12:00 | E5: =RIGHT(exp_SILP!$R5,5) -> 14:00 | F5: =IF(exp_SILP!$AG5>=60,exp_SILP!$AG5/60,exp_SILP!$AG5) -> 2 | G5: =VLOOKUP(exp_SILP!$Y5,'DATI CM'!$A$2:$F$28,2,FALSE) -> PNFMRT85H50A859E | H5: =VLOOKUP(exp_SILP!$Y5,'DATI CM'!$A$2:$F$28,3,FALSE) -> A011 | I5: =IF(A5>0,"N","N") -> N | J5: =VLOOKUP(exp_SILP!$Y5,'DATI CM'!$A$2:$F$28,4,FALSE) -> BIELLA | K5: =VLOOKUP(exp_SILP!$B5,'DATI COMMESSE'!$A$2:$F$25,5,FALSE) -> 39.94 | L5: =IF(exp_SILP!$B5="A4.10 - LEP E - ORIENTAMENTO SPECIALISTICO SKILL GAP ANALYSIS - GRUPPO 3P",0,VLOOKUP(exp_SILP!$Y5,'DATI CM'!$A$2:$F$28,6,FALSE)) -> 25 | M5: =IFERROR(VLOOKUP(exp_SILP!$B5,'DATI CM'!$H$2:$I$16,2,FALSE)*exp_SILP!$F5,0) -> 0 | N5: =VLOOKUP(exp_SILP!$B5,'DATI COMMESSE'!$A$2:$F$25,4,FALSE) -> GOL | O5: =VLOOKUP(exp_SILP!$B5,'DATI COMMESSE'!$A$2:$F$25,5,FALSE)*exp_SILP!$F5 -> 79.88 | P5: =IF(MID(exp_SILP!$W5,10,2)>"40","F","M") -> M | Q5: 01/02/2023 | R5: 12:00-14:00 | S5: A4.10 - LEP E - ORIENTAMENTO SPECIALISTICO SKILL GAP ANALYSIS | T5: Progetti per accreditati | V5: MINTENKU SERHII | W5: MNTSRH76E27Z138U | X5: 27/05/1976 | Y5: PIANOFORTE MARTA | Z5: Erogato | AA5: INFORCOOP ECIPA PIEMONTE | AB5: Incontro MDL | AC5: INFORCOOP ECIPA PIEMONTE STRADA CAMPAGNE' 7 - BIELLA | AG5: 120 | AH5: 01/02/2023 | AI5: PNFMRT85H50A859E | AJ5: =VLOOKUP(exp_SILP!$Y5,'DATI CM'!$A$2:$F$28,2,FALSE) -> PNFMRT85H50A859E
A6: =IFERROR(VLOOKUP(exp_SILP!$W6,exp_utenti_P!D:D,1,FALSE),"_DA INSERIRE") -> RSNMRA72A46D872J | B6: =IF(AND(exp_SILP!$S6="A.3 ORIENTAMENTO PROFESSIONALE",exp_SILP!$AD6="4.2"),"A.3 ORIENTAMENTO PROFESSIONALE (CARCERE)", IF(AND(exp_SILP!$S6="A.3 ORIENTAMENTO PROFESSIONALE",exp_SILP!$AD6="."),"A.3 ORIENTAMENTO PROFESSIONALE (CARCERE)", IF(AND(exp_SILP!$S6="A.4 CONSULENZA ORIENTATIVA",exp_SILP!$AD6="4.2"),"A.4 CONSULENZA ORIENTATIVA (CARCERE)", IF(AND(exp_SILP!$S6="A.4 CONSULENZA ORIENTATIVA",exp_SILP!$AD6="."),"A.4 CONSULENZA ORIENTATIVA (CARCERE)", IF(AND(exp_SILP!$S6="A.5 - LEP F1 - ACCOMPAGNAMENTO AL LAVORO",exp_SILP!$AD6="4.2"),"A.5 - LEP F1 - ACCOMPAGNAMENTO AL LAVORO (CARCERE)", IF(AND(exp_SILP!$S6="A.5 - LEP F1 - ACCOMPAGNAMENTO AL LAVORO",exp_SILP!$AD6="."),"A.5 - LEP F1 - ACCOMPAGNAMENTO AL LAVORO (CARCERE)", IF(AND(exp_SILP!$S6="A.5.2a - TUTORAGGIO TIROCINI",exp_SILP!$AD6="4.2"),"A.5.2a - TUTORAGGIO TIROCINI (CARCERE)", exp_SILP!$S6))))))) -> A4.10 - LEP E - ORIENTAMENTO SPECIALISTICO SKILL GAP ANALYSIS | C6: =CONCATENATE(VLOOKUP(exp_SILP!$B6,'DATI COMMESSE'!$A$2:$F$25,4,FALSE)," - ", VLOOKUP(exp_SILP!$B6,'DATI COMMESSE'!$A$2:$F$25,2,FALSE)," - ",VLOOKUP(exp_SILP!$B6,'DATI COMMESSE'!$A$2:$F$25,3,FALSE)) -> GOL - 22-02-5000 - 22-12-5003 | D6: =LEFT(exp_SILP!$R6,5) -> 11:30 | E6: =RIGHT(exp_SILP!$R6,5) -> 13:30 | F6: =IF(exp_SILP!$AG6>=60,exp_SILP!$AG6/60,exp_SILP!$AG6) -> 2 | G6: =VLOOKUP(exp_SILP!$Y6,'DATI CM'!$A$2:$F$28,2,FALSE) -> TRZCST69B41F952V | H6: =VLOOKUP(exp_SILP!$Y6,'DATI CM'!$A$2:$F$28,3,FALSE) | I6: =IF(A6>0,"N","N") -> N | J6: =VLOOKUP(exp_SILP!$Y6,'DATI CM'!$A$2:$F$28,4,FALSE) | K6: =VLOOKUP(exp_SILP!$B6,'DATI COMMESSE'!$A$2:$F$25,5,FALSE) -> 39.94 | L6: =IF(exp_SILP!$B6="A4.10 - LEP E - ORIENTAMENTO SPECIALISTICO SKILL GAP ANALYSIS - GRUPPO 3P",0,VLOOKUP(exp_SILP!$Y6,'DATI CM'!$A$2:$F$28,6,FALSE)) | M6: =IFERROR(VLOOKUP(exp_SILP!$B6,'DATI CM'!$H$2:$I$16,2,FALSE)*exp_SILP!$F6,0) -> 0 | N6: =VLOOKUP(exp_SILP!$B6,'DATI COMMESSE'!$A$2:$F$25,4,FALSE) -> GOL | O6: =VLOOKUP(exp_SILP!$B6,'DATI COMMESSE'!$A$2:$F$25,5,FALSE)*exp_SILP!$F6 -> 79.88 | P6: =IF(MID(exp_SILP!$W6,10,2)>"40","F","M") -> F | Q6: 01/02/2023 | R6: 11:30-13:30 | S6: A4.10 - LEP E - ORIENTAMENTO SPECIALISTICO SKILL GAP ANALYSIS | T6: Progetti per accreditati | V6: ORSINA MARA | W6: RSNMRA72A46D872J | X6: 06/01/1972 | Y6: TERZERA CRISTINA | Z6: Erogato | AA6: INFORCOOP ECIPA PIEMONTE | AB6: Incontro MDL | AC6: INFORCOOP ECIPA PIEMONTE VIA UGO PORZIO GIOVANOLA 7 - NOVARA | AG6: 120 | AH6: 01/02/2023 | AI6: TRZCST69B41F952V | AJ6: =VLOOKUP(exp_SILP!$Y6,'DATI CM'!$A$2:$F$28,2,FALSE) -> TRZCST69B41F952V
A7: =IFERROR(VLOOKUP(exp_SILP!$W7,exp_utenti_P!D:D,1,FALSE),"_DA INSERIRE") -> MTAGRG64C06Z129P | B7: =IF(AND(exp_SILP!$S7="A.3 ORIENTAMENTO PROFESSIONALE",exp_SILP!$AD7="4.2"),"A.3 ORIENTAMENTO PROFESSIONALE (CARCERE)", IF(AND(exp_SILP!$S7="A.3 ORIENTAMENTO PROFESSIONALE",exp_SILP!$AD7="."),"A.3 ORIENTAMENTO PROFESSIONALE (CARCERE)", IF(AND(exp_SILP!$S7="A.4 CONSULENZA ORIENTATIVA",exp_SILP!$AD7="4.2"),"A.4 CONSULENZA ORIENTATIVA (CARCERE)", IF(AND(exp_SILP!$S7="A.4 CONSULENZA ORIENTATIVA",exp_SILP!$AD7="."),"A.4 CONSULENZA ORIENTATIVA (CARCERE)", IF(AND(exp_SILP!$S7="A.5 - LEP F1 - ACCOMPAGNAMENTO AL LAVORO",exp_SILP!$AD7="4.2"),"A.5 - LEP F1 - ACCOMPAGNAMENTO AL LAVORO (CARCERE)", IF(AND(exp_SILP!$S7="A.5 - LEP F1 - ACCOMPAGNAMENTO AL LAVORO",exp_SILP!$AD7="."),"A.5 - LEP F1 - ACCOMPAGNAMENTO AL LAVORO (CARCERE)", IF(AND(exp_SILP!$S7="A.5.2a - TUTORAGGIO TIROCINI",exp_SILP!$AD7="4.2"),"A.5.2a - TUTORAGGIO TIROCINI (CARCERE)", exp_SILP!$S7))))))) -> A.4 CONSULENZA ORIENTATIVA (1-C) | C7: =CONCATENATE(VLOOKUP(exp_SILP!$B7,'DATI COMMESSE'!$A$2:$F$25,4,FALSE)," - ", VLOOKUP(exp_SILP!$B7,'DATI COMMESSE'!$A$2:$F$25,2,FALSE)," - ",VLOOKUP(exp_SILP!$B7,'DATI COMMESSE'!$A$2:$F$25,3,FALSE)) -> FRD - 22-02-5000 - 22-12-5002 | D7: =LEFT(exp_SILP!$R7,5) -> 17:00 | E7: =RIGHT(exp_SILP!$R7,5) -> 18:00 | F7: =IF(exp_SILP!$AG7>=60,exp_SILP!$AG7/60,exp_SILP!$AG7) -> 1 | G7: =VLOOKUP(exp_SILP!$Y7,'DATI CM'!$A$2:$F$28,2,FALSE) -> FLCSRN79S42L219X | H7: =VLOOKUP(exp_SILP!$Y7,'DATI CM'!$A$2:$F$28,3,FALSE) -> A011 | I7: =IF(A7>0,"N","N") -> N | J7: =VLOOKUP(exp_SILP!$Y7,'DATI CM'!$A$2:$F$28,4,FALSE) -> TORINO | K7: =VLOOKUP(exp_SILP!$B7,'DATI COMMESSE'!$A$2:$F$25,5,FALSE) -> 35.5 | L7: =IF(exp_SILP!$B7="A4.10 - LEP E - ORIENTAMENTO SPECIALISTICO SKILL GAP ANALYSIS - GRUPPO 3P",0,VLOOKUP(exp_SILP!$Y7,'DATI CM'!$A$2:$F$28,6,FALSE)) -> 25 | M7: =IFERROR(VLOOKUP(exp_SILP!$B7,'DATI CM'!$H$2:$I$16,2,FALSE)*exp_SILP!$F7,0) -> 0 | N7: =VLOOKUP(exp_SILP!$B7,'DATI COMMESSE'!$A$2:$F$25,4,FALSE) -> FRD | O7: =VLOOKUP(exp_SILP!$B7,'DATI COMMESSE'!$A$2:$F$25,5,FALSE)*exp_SILP!$F7 -> 35.5 | P7: =IF(MID(exp_SILP!$W7,10,2)>"40","F","M") -> M | Q7: 01/03/2023 | R7: 17:00-18:00 | S7: A.4 CONSULENZA ORIENTATIVA (1-C) | T7: Progetti per accreditati | V7: MATEI GHEORGHE | W7: MTAGRG64C06Z129P | X7: 06/03/1964 | Y7: FALCONE SERENA | Z7: Erogato | AA7: INFORCOOP ECIPA PIEMONTE | AB7: Incontro MDL | AC7: INFORCOOP ECIPA PIEMONTE VIA LIVORNO 53/b - TORINO | AF7: BACK OFFICE | AG7: 60 | AH7: 03/03/2023 | AI7: FLCSRN79S42L219X | AJ7: =VLOOKUP(exp_SILP!$Y7,'DATI CM'!$A$2:$F$28,2,FALSE) -> FLCSRN79S42L219X
A8: =IFERROR(VLOOKUP(exp_SILP!$W8,exp_utenti_P!D:D,1,FALSE),"_DA INSERIRE") -> MTAGRG64C06Z129P | B8: =IF(AND(exp_SILP!$S8="A.3 ORIENTAMENTO PROFESSIONALE",exp_SILP!$AD8="4.2"),"A.3 ORIENTAMENTO PROFESSIONALE (CARCERE)", IF(AND(exp_SILP!$S8="A.3 ORIENTAMENTO PROFESSIONALE",exp_SILP!$AD8="."),"A.3 ORIENTAMENTO PROFESSIONALE (CARCERE)", IF(AND(exp_SILP!$S8="A.4 CONSULENZA ORIENTATIVA",exp_SILP!$AD8="4.2"),"A.4 CONSULENZA ORIENTATIVA (CARCERE)", IF(AND(exp_SILP!$S8="A.4 CONSULENZA ORIENTATIVA",exp_SILP!$AD8="."),"A.4 CONSULENZA ORIENTATIVA (CARCERE)", IF(AND(exp_SILP!$S8="A.5 - LEP F1 - ACCOMPAGNAMENTO AL LAVORO",exp_SILP!$AD8="4.2"),"A.5 - LEP F1 - ACCOMPAGNAMENTO AL LAVORO (CARCERE)", IF(AND(exp_SILP!$S8="A.5 - LEP F1 - ACCOMPAGNAMENTO AL LAVORO",exp_SILP!$AD8="."),"A.5 - LEP F1 - ACCOMPAGNAMENTO AL LAVORO (CARCERE)", IF(AND(exp_SILP!$S8="A.5.2a - TUTORAGGIO TIROCINI",exp_SILP!$AD8="4.2"),"A.5.2a - TUTORAGGIO TIROCINI (CARCERE)", exp_SILP!$S8))))))) -> A.4 CONSULENZA ORIENTATIVA (1-C) | C8: =CONCATENATE(VLOOKUP(exp_SILP!$B8,'DATI COMMESSE'!$A$2:$F$25,4,FALSE)," - ", VLOOKUP(exp_SILP!$B8,'DATI COMMESSE'!$A$2:$F$25,2,FALSE)," - ",VLOOKUP(exp_SILP!$B8,'DATI COMMESSE'!$A$2:$F$25,3,FALSE)) -> FRD - 22-02-5000 - 22-12-5002 | D8: =LEFT(exp_SILP!$R8,5) -> 14:00 | E8: =RIGHT(exp_SILP!$R8,5) -> 17:00 | F8: =IF(exp_SILP!$AG8>=60,exp_SILP!$AG8/60,exp_SILP!$AG8) -> 3 | G8: =VLOOKUP(exp_SILP!$Y8,'DATI CM'!$A$2:$F$28,2,FALSE) -> FLCSRN79S42L219X | H8: =VLOOKUP(exp_SILP!$Y8,'DATI CM'!$A$2:$F$28,3,FALSE) -> A011 | I8: =IF(A8>0,"N","N") -> N | J8: =VLOOKUP(exp_SILP!$Y8,'DATI CM'!$A$2:$F$28,4,FALSE) -> TORINO | K8: =VLOOKUP(exp_SILP!$B8,'DATI COMMESSE'!$A$2:$F$25,5,FALSE) -> 35.5 | L8: =IF(exp_SILP!$B8="A4.10 - LEP E - ORIENTAMENTO SPECIALISTICO SKILL GAP ANALYSIS - GRUPPO 3P",0,VLOOKUP(exp_SILP!$Y8,'DATI CM'!$A$2:$F$28,6,FALSE)) -> 25 | M8: =IFERROR(VLOOKUP(exp_SILP!$B8,'DATI CM'!$H$2:$I$16,2,FALSE)*exp_SILP!$F8,0) -> 0 | N8: =VLOOKUP(exp_SILP!$B8,'DATI COMMESSE'!$A$2:$F$25,4,FALSE) -> FRD | O8: =VLOOKUP(exp_SILP!$B8,'DATI COMMESSE'!$A$2:$F$25,5,FALSE)*exp_SILP!$F8 -> 106.5 | P8: =IF(MID(exp_SILP!$W8,10,2)>"40","F","M") -> M | Q8: 01/03/2023 | R8: 14:00-17:00 | S8: A.4 CONSULENZA ORIENTATIVA (1-C) | T8: Progetti per accreditati | V8: MATEI GHEORGHE | W8: MTAGRG64C06Z129P | X8: 06/03/1964 | Y8: FALCONE SERENA | Z8: Erogato | AA8: INFORCOOP ECIPA PIEMONTE | AB8: Incontro MDLpresentato | AC8: INFORCOOP ECIPA PIEMONTE VIA LIVORNO 53/b - TORINO | AG8: 180 | AH8: 03/03/2023 | AI8: FLCSRN79S42L219X | AJ8: =VLOOKUP(exp_SILP!$Y8,'DATI CM'!$A$2:$F$28,2,FALSE) -> FLCSRN79S42L219X
A9: =IFERROR(VLOOKUP(exp_SILP!$W9,exp_utenti_P!D:D,1,FALSE),"_DA INSERIRE") -> BRTJNY00R63L219O | B9: =IF(AND(exp_SILP!$S9="A.3 ORIENTAMENTO PROFESSIONALE",exp_SILP!$AD9="4.2"),"A.3 ORIENTAMENTO PROFESSIONALE (CARCERE)", IF(AND(exp_SILP!$S9="A.3 ORIENTAMENTO PROFESSIONALE",exp_SILP!$AD9="."),"A.3 ORIENTAMENTO PROFESSIONALE (CARCERE)", IF(AND(exp_SILP!$S9="A.4 CONSULENZA ORIENTATIVA",exp_SILP!$AD9="4.2"),"A.4 CONSULENZA ORIENTATIVA (CARCERE)", IF(AND(exp_SILP!$S9="A.4 CONSULENZA ORIENTATIVA",exp_SILP!$AD9="."),"A.4 CONSULENZA ORIENTATIVA (CARCERE)", IF(AND(exp_SILP!$S9="A.5 - LEP F1 - ACCOMPAGNAMENTO AL LAVORO",exp_SILP!$AD9="4.2"),"A.5 - LEP F1 - ACCOMPAGNAMENTO AL LAVORO (CARCERE)", IF(AND(exp_SILP!$S9="A.5 - LEP F1 - ACCOMPAGNAMENTO AL LAVORO",exp_SILP!$AD9="."),"A.5 - LEP F1 - ACCOMPAGNAMENTO AL LAVORO (CARCERE)", IF(AND(exp_SILP!$S9="A.5.2a - TUTORAGGIO TIROCINI",exp_SILP!$AD9="4.2"),"A.5.2a - TUTORAGGIO TIROCINI (CARCERE)", exp_SILP!$S9))))))) -> A.4 CONSULENZA ORIENTATIVA (1-C) | C9: =CONCATENATE(VLOOKUP(exp_SILP!$B9,'DATI COMMESSE'!$A$2:$F$25,4,FALSE)," - ", VLOOKUP(exp_SILP!$B9,'DATI COMMESSE'!$A$2:$F$25,2,FALSE)," - ",VLOOKUP(exp_SILP!$B9,'DATI COMMESSE'!$A$2:$F$25,3,FALSE)) -> FRD - 22-02-5000 - 22-12-5002 | D9: =LEFT(exp_SILP!$R9,5) -> 12:00 | E9: =RIGHT(exp_SILP!$R9,5) -> 13:00 | F9: =IF(exp_SILP!$AG9>=60,exp_SILP!$AG9/60,exp_SILP!$AG9) -> 1 | G9: =VLOOKUP(exp_SILP!$Y9,'DATI CM'!$A$2:$F$28,2,FALSE) -> FLCSRN79S42L219X | H9: =VLOOKUP(exp_SILP!$Y9,'DATI CM'!$A$2:$F$28,3,FALSE) -> A011 | I9: =IF(A9>0,"N","N") -> N | J9: =VLOOKUP(exp_SILP!$Y9,'DATI CM'!$A$2:$F$28,4,FALSE) -> TORINO | K9: =VLOOKUP(exp_SILP!$B9,'DATI COMMESSE'!$A$2:$F$25,5,FALSE) -> 35.5 | L9: =IF(exp_SILP!$B9="A4.10 - LEP E - ORIENTAMENTO SPECIALISTICO SKILL GAP ANALYSIS - GRUPPO 3P",0,VLOOKUP(exp_SILP!$Y9,'DATI CM'!$A$2:$F$28,6,FALSE)) -> 25 | M9: =IFERROR(VLOOKUP(exp_SILP!$B9,'DATI CM'!$H$2:$I$16,2,FALSE)*exp_SILP!$F9,0) -> 0 | N9: =VLOOKUP(exp_SILP!$B9,'DATI COMMESSE'!$A$2:$F$25,4,FALSE) -> FRD | O9: =VLOOKUP(exp_SILP!$B9,'DATI COMMESSE'!$A$2:$F$25,5,FALSE)*exp_SILP!$F9 -> 35.5 | P9: =IF(MID(exp_SILP!$W9,10,2)>"40","F","M") -> F | Q9: 01/03/2023 | R9: 12:00-13:00 | S9: A.4 CONSULENZA ORIENTATIVA (1-C) | T9: Progetti per accreditati | V9: BERTAGGIA JENNY | W9: BRTJNY00R63L219O | X9: 23/10/2000 | Y9: FALCONE SERENA | Z9: Erogato | AA9: INFORCOOP ECIPA PIEMONTE | AB9: Incontro MDLpresentato | AC9: INFORCOOP ECIPA PIEMONTE VIA LIVORNO 53/b - TORINO | AG9: 60 | AH9: 01/03/2023 | AI9: FLCSRN79S42L219X | AJ9: =VLOOKUP(exp_SILP!$Y9,'DATI CM'!$A$2:$F$28,2,FALSE) -> FLCSRN79S42L219X
A10: =IFERROR(VLOOKUP(exp_SILP!$W10,exp_utenti_P!D:D,1,FALSE),"_DA INSERIRE") -> STRGRY71L08C627Y | B10: =IF(AND(exp_SILP!$S10="A.3 ORIENTAMENTO PROFESSIONALE",exp_SILP!$AD10="4.2"),"A.3 ORIENTAMENTO PROFESSIONALE (CARCERE)", IF(AND(exp_SILP!$S10="A.3 ORIENTAMENTO PROFESSIONALE",exp_SILP!$AD10="."),"A.3 ORIENTAMENTO PROFESSIONALE (CARCERE)", IF(AND(exp_SILP!$S10="A.4 CONSULENZA ORIENTATIVA",exp_SILP!$AD10="4.2"),"A.4 CONSULENZA ORIENTATIVA (CARCERE)", IF(AND(exp_SILP!$S10="A.4 CONSULENZA ORIENTATIVA",exp_SILP!$AD10="."),"A.4 CONSULENZA ORIENTATIVA (CARCERE)", IF(AND(exp_SILP!$S10="A.5 - LEP F1 - ACCOMPAGNAMENTO AL LAVORO",exp_SILP!$AD10="4.2"),"A.5 - LEP F1 - ACCOMPAGNAMENTO AL LAVORO (CARCERE)", IF(AND(exp_SILP!$S10="A.5 - LEP F1 - ACCOMPAGNAMENTO AL LAVORO",exp_SILP!$AD10="."),"A.5 - LEP F1 - ACCOMPAGNAMENTO AL LAVORO (CARCERE)", IF(AND(exp_SILP!$S10="A.5.2a - TUTORAGGIO TIROCINI",exp_SILP!$AD10="4.2"),"A.5.2a - TUTORAGGIO TIROCINI (CARCERE)", exp_SILP!$S10))))))) -> A4.10 - LEP E - ORIENTAMENTO SPECIALISTICO SKILL GAP ANALYSIS | C10: =CONCATENATE(VLOOKUP(exp_SILP!$B10,'DATI COMMESSE'!$A$2:$F$25,4,FALSE)," - ", VLOOKUP(exp_SILP!$B10,'DATI COMMESSE'!$A$2:$F$25,2,FALSE)," - ",VLOOKUP(exp_SILP!$B10,'DATI COMMESSE'!$A$2:$F$25,3,FALSE)) -> GOL - 22-02-5000 - 22-12-5003 | D10: =LEFT(exp_SILP!$R10,5) -> 09:00 | E10: =RIGHT(exp_SILP!$R10,5) -> 12:00 | F10: =IF(exp_SILP!$AG10>=60,exp_SILP!$AG10/60,exp_SILP!$AG10) -> 3 | G10: =VLOOKUP(exp_SILP!$Y10,'DATI CM'!$A$2:$F$28,2,FALSE) -> FLCSRN79S42L219X | H10: =VLOOKUP(exp_SILP!$Y10,'DATI CM'!$A$2:$F$28,3,FALSE) -> A011 | I10: =IF(A10>0,"N","N") -> N | J10: =VLOOKUP(exp_SILP!$Y10,'DATI CM'!$A$2:$F$28,4,FALSE) -> TORINO | K10: =VLOOKUP(exp_SILP!$B10,'DATI COMMESSE'!$A$2:$F$25,5,FALSE) -> 39.94 | L10: =IF(exp_SILP!$B10="A4.10 - LEP E - ORIENTAMENTO SPECIALISTICO SKILL GAP ANALYSIS - GRUPPO 3P",0,VLOOKUP(exp_SILP!$Y10,'DATI CM'!$A$2:$F$28,6,FALSE)) -> 25 | M10: =IFERROR(VLOOKUP(exp_SILP!$B10,'DATI CM'!$H$2:$I$16,2,FALSE)*exp_SILP!$F10,0) -> 0 | N10: =VLOOKUP(exp_SILP!$B10,'DATI COMMESSE'!$A$2:$F$25,4,FALSE) -> GOL | O10: =VLOOKUP(exp_SILP!$B10,'DATI COMMESSE'!$A$2:$F$25,5,FALSE)*exp_SILP!$F10 -> 119.82 | P10: =IF(MID(exp_SILP!$W10,10,2)>"40","F","M") -> M | Q10: 01/03/2023 | R10: 09:00-12:00 | S10: A4.10 - LEP E - ORIENTAMENTO SPECIALISTICO SKILL GAP ANALYSIS | T10: Progetti per accreditati | V10: STRIANO GERRY | W10: STRGRY71L08C627Y | X10: 08/07/1971 | Y10: FALCONE SERENA | Z10: Erogato | AA10: INFORCOOP ECIPA PIEMONTE | AB10: Incontro MDLpresentato | AC10: INFORCOOP ECIPA PIEMONTE VIA LIVORNO 53/b - TORINO | AG10: 180 | AH10: 01/03/2023 | AI10: FLCSRN79S42L219X | AJ10: =VLOOKUP(exp_SILP!$Y10,'DATI CM'!$A$2:$F$28,2,FALSE) -> FLCSRN79S42L219X
A11: =IFERROR(VLOOKUP(exp_SILP!$W11,exp_utenti_P!D:D,1,FALSE),"_DA INSERIRE") -> DMAGPP68A02C352O | B11: =IF(AND(exp_SILP!$S11="A.3 ORIENTAMENTO PROFESSIONALE",exp_SILP!$AD11="4.2"),"A.3 ORIENTAMENTO PROFESSIONALE (CARCERE)", IF(AND(exp_SILP!$S11="A.3 ORIENTAMENTO PROFESSIONALE",exp_SILP!$AD11="."),"A.3 ORIENTAMENTO PROFESSIONALE (CARCERE)", IF(AND(exp_SILP!$S11="A.4 CONSULENZA ORIENTATIVA",exp_SILP!$AD11="4.2"),"A.4 CONSULENZA ORIENTATIVA (CARCERE)", IF(AND(exp_SILP!$S11="A.4 CONSULENZA ORIENTATIVA",exp_SILP!$AD11="."),"A.4 CONSULENZA ORIENTATIVA (CARCERE)", IF(AND(exp_SILP!$S11="A.5 - LEP F1 - ACCOMPAGNAMENTO AL LAVORO",exp_SILP!$AD11="4.2"),"A.5 - LEP F1 - ACCOMPAGNAMENTO AL LAVORO (CARCERE)", IF(AND(exp_SILP!$S11="A.5 - LEP F1 - ACCOMPAGNAMENTO AL LAVORO",exp_SILP!$AD11="."),"A.5 - LEP F1 - ACCOMPAGNAMENTO AL LAVORO (CARCERE)", IF(AND(exp_SILP!$S11="A.5.2a - TUTORAGGIO TIROCINI",exp_SILP!$AD11="4.2"),"A.5.2a - TUTORAGGIO TIROCINI (CARCERE)", exp_SILP!$S11))))))) -> A4.10 - LEP E - ORIENTAMENTO SPECIALISTICO SKILL GAP ANALYSIS | C11: =CONCATENATE(VLOOKUP(exp_SILP!$B11,'DATI COMMESSE'!$A$2:$F$25,4,FALSE)," - ", VLOOKUP(exp_SILP!$B11,'DATI COMMESSE'!$A$2:$F$25,2,FALSE)," - ",VLOOKUP(exp_SILP!$B11,'DATI COMMESSE'!$A$2:$F$25,3,FALSE)) -> GOL - 22-02-5000 - 22-12-5003 | D11: =LEFT(exp_SILP!$R11,5) -> 16:30 | E11: =RIGHT(exp_SILP!$R11,5) -> 17:30 | F11: =IF(exp_SILP!$AG11>=60,exp_SILP!$AG11/60,exp_SILP!$AG11) -> 1 | G11: =VLOOKUP(exp_SILP!$Y11,'DATI CM'!$A$2:$F$28,2,FALSE) -> TRZCST69B41F952V | H11: =VLOOKUP(exp_SILP!$Y11,'DATI CM'!$A$2:$F$28,3,FALSE) | I11: =IF(A11>0,"N","N") -> N | J11: =VLOOKUP(exp_SILP!$Y11,'DATI CM'!$A$2:$F$28,4,FALSE) | K11: =VLOOKUP(exp_SILP!$B11,'DATI COMMESSE'!$A$2:$F$25,5,FALSE) -> 39.94 | L11: =IF(exp_SILP!$B11="A4.10 - LEP E - ORIENTAMENTO SPECIALISTICO SKILL GAP ANALYSIS - GRUPPO 3P",0,VLOOKUP(exp_SILP!$Y11,'DATI CM'!$A$2:$F$28,6,FALSE)) | M11: =IFERROR(VLOOKUP(exp_SILP!$B11,'DATI CM'!$H$2:$I$16,2,FALSE)*exp_SILP!$F11,0) -> 0 | N11: =VLOOKUP(exp_SILP!$B11,'DATI COMMESSE'!$A$2:$F$25,4,FALSE) -> GOL | O11: =VLOOKUP(exp_SILP!$B11,'DATI COMMESSE'!$A$2:$F$25,5,FALSE)*exp_SILP!$F11 -> 39.94 | P11: =IF(MID(exp_SILP!$W11,10,2)>"40","F","M") -> M | Q11: 01/03/2023 | R11: 16:30-17:30 | S11: A4.10 - LEP E - ORIENTAMENTO SPECIALISTICO SKILL GAP ANALYSIS | T11: Progetti per accreditati | V11: ADAMO GIUSEPPE | W11: DMAGPP68A02C352O | X11: 02/01/1968 | Y11: TERZERA CRISTINA | Z11: Erogato | AA11: INFORCOOP ECIPA PIEMONTE | AB11: Incontro MDL | AC11: INFORCOOP ECIPA PIEMONTE VIA UGO PORZIO GIOVANOLA 7 - NOVARA | AF11: BACK OFFICE | AG11: 60 | AH11: 20/04/2023 | AI11: TRZCST69B41F952V | AJ11: =VLOOKUP(exp_SILP!$Y11,'DATI CM'!$A$2:$F$28,2,FALSE) -> TRZCST69B41F952V
A12: =IFERROR(VLOOKUP(exp_SILP!$W12,exp_utenti_P!D:D,1,FALSE),"_DA INSERIRE") -> RSSMSM71T04A010O | B12: =IF(AND(exp_SILP!$S12="A.3 ORIENTAMENTO PROFESSIONALE",exp_SILP!$AD12="4.2"),"A.3 ORIENTAMENTO PROFESSIONALE (CARCERE)", IF(AND(exp_SILP!$S12="A.3 ORIENTAMENTO PROFESSIONALE",exp_SILP!$AD12="."),"A.3 ORIENTAMENTO PROFESSIONALE (CARCERE)", IF(AND(exp_SILP!$S12="A.4 CONSULENZA ORIENTATIVA",exp_SILP!$AD12="4.2"),"A.4 CONSULENZA ORIENTATIVA (CARCERE)", IF(AND(exp_SILP!$S12="A.4 CONSULENZA ORIENTATIVA",exp_SILP!$AD12="."),"A.4 CONSULENZA ORIENTATIVA (CARCERE)", IF(AND(exp_SILP!$S12="A.5 - LEP F1 - ACCOMPAGNAMENTO AL LAVORO",exp_SILP!$AD12="4.2"),"A.5 - LEP F1 - ACCOMPAGNAMENTO AL LAVORO (CARCERE)", IF(AND(exp_SILP!$S12="A.5 - LEP F1 - ACCOMPAGNAMENTO AL LAVORO",exp_SILP!$AD12="."),"A.5 - LEP F1 - ACCOMPAGNAMENTO AL LAVORO (CARCERE)", IF(AND(exp_SILP!$S12="A.5.2a - TUTORAGGIO TIROCINI",exp_SILP!$AD12="4.2"),"A.5.2a - TUTORAGGIO TIROCINI (CARCERE)", exp_SILP!$S12))))))) -> A4.10 - LEP E - ORIENTAMENTO SPECIALISTICO SKILL GAP ANALYSIS | C12: =CONCATENATE(VLOOKUP(exp_SILP!$B12,'DATI COMMESSE'!$A$2:$F$25,4,FALSE)," - ", VLOOKUP(exp_SILP!$B12,'DATI COMMESSE'!$A$2:$F$25,2,FALSE)," - ",VLOOKUP(exp_SILP!$B12,'DATI COMMESSE'!$A$2:$F$25,3,FALSE)) -> GOL - 22-02-5000 - 22-12-5003 | D12: =LEFT(exp_SILP!$R12,5) -> 15:30 | E12: =RIGHT(exp_SILP!$R12,5) -> 16:30 | F12: =IF(exp_SILP!$AG12>=60,exp_SILP!$AG12/60,exp_SILP!$AG12) -> 1 | G12: =VLOOKUP(exp_SILP!$Y12,'DATI CM'!$A$2:$F$28,2,FALSE) -> TRZCST69B41F952V | H12: =VLOOKUP(exp_SILP!$Y12,'DATI CM'!$A$2:$F$28,3,FALSE) | I12: =IF(A12>0,"N","N") -> N | J12: =VLOOKUP(exp_SILP!$Y12,'DATI CM'!$A$2:$F$28,4,FALSE) | K12: =VLOOKUP(exp_SILP!$B12,'DATI COMMESSE'!$A$2:$F$25,5,FALSE) -> 39.94 | L12: =IF(exp_SILP!$B12="A4.10 - LEP E - ORIENTAMENTO SPECIALISTICO SKILL GAP ANALYSIS - GRUPPO 3P",0,VLOOKUP(exp_SILP!$Y12,'DATI CM'!$A$2:$F$28,6,FALSE)) | M12: =IFERROR(VLOOKUP(exp_SILP!$B12,'DATI CM'!$H$2:$I$16,2,FALSE)*exp_SILP!$F12,0) -> 0 | N12: =VLOOKUP(exp_SILP!$B12,'DATI COMMESSE'!$A$2:$F$25,4,FALSE) -> GOL | O12: =VLOOKUP(exp_SILP!$B12,'DATI COMMESSE'!$A$2:$F$25,5,FALSE)*exp_SILP!$F12 -> 39.94 | P12: =IF(MID(exp_SILP!$W12,10,2)>"40","F","M") -> M | Q12: 01/03/2023 | R12: 15:30-16:30 | S12: A4.10 - LEP E - ORIENTAMENTO SPECIALISTICO SKILL GAP ANALYSIS | T12: Progetti per accreditati | V12: RUSSO MASSIMO | W12: RSSMSM71T04A010O | X12: 04/12/1971 | Y12: TERZERA CRISTINA | Z12: Erogato | AA12: INFORCOOP ECIPA PIEMONTE | AB12: Incontro MDL | AC12: INFORCOOP ECIPA PIEMONTE VIA UGO PORZIO GIOVANOLA 7 - NOVARA | AG12: 60 | AH12: 10/03/2023 | AI12: TRZCST69B41F952V | AJ12: =VLOOKUP(exp_SILP!$Y12,'DATI CM'!$A$2:$F$28,2,FALSE) -> TRZCST69B41F952V
A13: =IFERROR(VLOOKUP(exp_SILP!$W13,exp_utenti_P!D:D,1,FALSE),"_DA INSERIRE") -> CLNNLS04L23F952V | B13: =IF(AND(exp_SILP!$S13="A.3 ORIENTAMENTO PROFESSIONALE",exp_SILP!$AD13="4.2"),"A.3 ORIENTAMENTO PROFESSIONALE (CARCERE)", IF(AND(exp_SILP!$S13="A.3 ORIENTAMENTO PROFESSIONALE",exp_SILP!$AD13="."),"A.3 ORIENTAMENTO PROFESSIONALE (CARCERE)", IF(AND(exp_SILP!$S13="A.4 CONSULENZA ORIENTATIVA",exp_SILP!$AD13="4.2"),"A.4 CONSULENZA ORIENTATIVA (CARCERE)", IF(AND(exp_SILP!$S13="A.4 CONSULENZA ORIENTATIVA",exp_SILP!$AD13="."),"A.4 CONSULENZA ORIENTATIVA (CARCERE)", IF(AND(exp_SILP!$S13="A.5 - LEP F1 - ACCOMPAGNAMENTO AL LAVORO",exp_SILP!$AD13="4.2"),"A.5 - LEP F1 - ACCOMPAGNAMENTO AL LAVORO (CARCERE)", IF(AND(exp_SILP!$S13="A.5 - LEP F1 - ACCOMPAGNAMENTO AL LAVORO",exp_SILP!$AD13="."),"A.5 - LEP F1 - ACCOMPAGNAMENTO AL LAVORO (CARCERE)", IF(AND(exp_SILP!$S13="A.5.2a - TUTORAGGIO TIROCINI",exp_SILP!$AD13="4.2"),"A.5.2a - TUTORAGGIO TIROCINI (CARCERE)", exp_SILP!$S13))))))) -> A4.10 - LEP E - ORIENTAMENTO SPECIALISTICO SKILL GAP ANALYSIS | C13: =CONCATENATE(VLOOKUP(exp_SILP!$B13,'DATI COMMESSE'!$A$2:$F$25,4,FALSE)," - ", VLOOKUP(exp_SILP!$B13,'DATI COMMESSE'!$A$2:$F$25,2,FALSE)," - ",VLOOKUP(exp_SILP!$B13,'DATI COMMESSE'!$A$2:$F$25,3,FALSE)) -> GOL - 22-02-5000 - 22-12-5003 | D13: =LEFT(exp_SILP!$R13,5) -> 14:30 | E13: =RIGHT(exp_SILP!$R13,5) -> 15:30 | F13: =IF(exp_SILP!$AG13>=60,exp_SILP!$AG13/60,exp_SILP!$AG13) -> 1 | G13: =VLOOKUP(exp_SILP!$Y13,'DATI CM'!$A$2:$F$28,2,FALSE) -> TRZCST69B41F952V | H13: =VLOOKUP(exp_SILP!$Y13,'DATI CM'!$A$2:$F$28,3,FALSE) | I13: =IF(A13>0,"N","N") -> N | J13: =VLOOKUP(exp_SILP!$Y13,'DATI CM'!$A$2:$F$28,4,FALSE) | K13: =VLOOKUP(exp_SILP!$B13,'DATI COMMESSE'!$A$2:$F$25,5,FALSE) -> 39.94 | L13: =IF(exp_SILP!$B13="A4.10 - LEP E - ORIENTAMENTO SPECIALISTICO SKILL GAP ANALYSIS - GRUPPO 3P",0,VLOOKUP(exp_SILP!$Y13,'DATI CM'!$A$2:$F$28,6,FALSE)) | M13: =IFERROR(VLOOKUP(exp_SILP!$B13,'DATI CM'!$H$2:$I$16,2,FALSE)*exp_SILP!$F13,0) -> 0 | N13: =VLOOKUP(exp_SILP!$B13,'DATI COMMESSE'!$A$2:$F$25,4,FALSE) -> GOL | O13: =VLOOKUP(exp_SILP!$B13,'DATI COMMESSE'!$A$2:$F$25,5,FALSE)*exp_SILP!$F13 -> 39.94 | P13: =IF(MID(exp_SILP!$W13,10,2)>"40","F","M") -> M | Q13: 01/03/2023 | R13: 14:30-15:30 | S13: A4.10 - LEP E - ORIENTAMENTO SPECIALISTICO SKILL GAP ANALYSIS | T13: Progetti per accreditati | V13: COLONNA NICOLAS | W13: CLNNLS04L23F952V | X13: 23/07/2004 | Y13: TERZERA CRISTINA | Z13: Erogato | AA13: INFORCOOP ECIPA PIEMONTE | AB13: Incontro MDL | AC13: INFORCOOP ECIPA PIEMONTE VIA UGO PORZIO GIOVANOLA 7 - NOVARA | AG13: 60 | AH13: 07/03/2023 | AI13: TRZCST69B41F952V | AJ13: =VLOOKUP(exp_SILP!$Y13,'DATI CM'!$A$2:$F$28,2,FALSE) -> TRZCST69B41F952V
A14: =IFERROR(VLOOKUP(exp_SILP!$W14,exp_utenti_P!D:D,1,FALSE),"_DA INSERIRE") -> CLNNLS04L23F952V | B14: =IF(AND(exp_SILP!$S14="A.3 ORIENTAMENTO PROFESSIONALE",exp_SILP!$AD14="4.2"),"A.3 ORIENTAMENTO PROFESSIONALE (CARCERE)", IF(AND(exp_SILP!$S14="A.3 ORIENTAMENTO PROFESSIONALE",exp_SILP!$AD14="."),"A.3 ORIENTAMENTO PROFESSIONALE (CARCERE)", IF(AND(exp_SILP!$S14="A.4 CONSULENZA ORIENTATIVA",exp_SILP!$AD14="4.2"),"A.4 CONSULENZA ORIENTATIVA (CARCERE)", IF(AND(exp_SILP!$S14="A.4 CONSULENZA ORIENTATIVA",exp_SILP!$AD14="."),"A.4 CONSULENZA ORIENTATIVA (CARCERE)", IF(AND(exp_SILP!$S14="A.5 - LEP F1 - ACCOMPAGNAMENTO AL LAVORO",exp_SILP!$AD14="4.2"),"A.5 - LEP F1 - ACCOMPAGNAMENTO AL LAVORO (CARCERE)", IF(AND(exp_SILP!$S14="A.5 - LEP F1 - ACCOMPAGNAMENTO AL LAVORO",exp_SILP!$AD14="."),"A.5 - LEP F1 - ACCOMPAGNAMENTO AL LAVORO (CARCERE)", IF(AND(exp_SILP!$S14="A.5.2a - TUTORAGGIO TIROCINI",exp_SILP!$AD14="4.2"),"A.5.2a - TUTORAGGIO TIROCINI (CARCERE)", exp_SILP!$S14))))))) -> A4.10 - LEP E - ORIENTAMENTO SPECIALISTICO SKILL GAP ANALYSIS | C14: =CONCATENATE(VLOOKUP(exp_SILP!$B14,'DATI COMMESSE'!$A$2:$F$25,4,FALSE)," - ", VLOOKUP(exp_SILP!$B14,'DATI COMMESSE'!$A$2:$F$25,2,FALSE)," - ",VLOOKUP(exp_SILP!$B14,'DATI COMMESSE'!$A$2:$F$25,3,FALSE)) -> GOL - 22-02-5000 - 22-12-5003 | D14: =LEFT(exp_SILP!$R14,5) -> 09:30 | E14: =RIGHT(exp_SILP!$R14,5) -> 12:30 | F14: =IF(exp_SILP!$AG14>=60,exp_SILP!$AG14/60,exp_SILP!$AG14) -> 3 | G14: =VLOOKUP(exp_SILP!$Y14,'DATI CM'!$A$2:$F$28,2,FALSE) -> TRZCST69B41F952V | H14: =VLOOKUP(exp_SILP!$Y14,'DATI CM'!$A$2:$F$28,3,FALSE) | I14: =IF(A14>0,"N","N") -> N | J14: =VLOOKUP(exp_SILP!$Y14,'DATI CM'!$A$2:$F$28,4,FALSE) | K14: =VLOOKUP(exp_SILP!$B14,'DATI COMMESSE'!$A$2:$F$25,5,FALSE) -> 39.94 | L14: =IF(exp_SILP!$B14="A4.10 - LEP E - ORIENTAMENTO SPECIALISTICO SKILL GAP ANALYSIS - GRUPPO 3P",0,VLOOKUP(exp_SILP!$Y14,'DATI CM'!$A$2:$F$28,6,FALSE)) | M14: =IFERROR(VLOOKUP(exp_SILP!$B14,'DATI CM'!$H$2:$I$16,2,FALSE)*exp_SILP!$F14,0) -> 0 | N14: =VLOOKUP(exp_SILP!$B14,'DATI COMMESSE'!$A$2:$F$25,4,FALSE) -> GOL | O14: =VLOOKUP(exp_SILP!$B14,'DATI COMMESSE'!$A$2:$F$25,5,FALSE)*exp_SILP!$F14 -> 119.82 | P14: =IF(MID(exp_SILP!$W14,10,2)>"40","F","M") -> M | Q14: 01/03/2023 | R14: 09:30-12:30 | S14: A4.10 - LEP E - ORIENTAMENTO SPECIALISTICO SKILL GAP ANALYSIS | T14: Progetti per accreditati | V14: COLONNA NICOLAS | W14: CLNNLS04L23F952V | X14: 23/07/2004 | Y14: TERZERA CRISTINA | Z14: Erogato | AA14: INFORCOOP ECIPA PIEMONTE | AB14: Incontro MDL | AC14: INFORCOOP ECIPA PIEMONTE VIA UGO PORZIO GIOVANOLA 7 - NOVARA | AG14: 180 | AH14: 01/03/2023 | AI14: TRZCST69B41F952V | AJ14: =VLOOKUP(exp_SILP!$Y14,'DATI CM'!$A$2:$F$28,2,FALSE) -> TRZCST69B41F952V
A15: =IFERROR(VLOOKUP(exp_SILP!$W15,exp_utenti_P!D:D,1,FALSE),"_DA INSERIRE") -> LEIGLC70M01F952G | B15: =IF(AND(exp_SILP!$S15="A.3 ORIENTAMENTO PROFESSIONALE",exp_SILP!$AD15="4.2"),"A.3 ORIENTAMENTO PROFESSIONALE (CARCERE)", IF(AND(exp_SILP!$S15="A.3 ORIENTAMENTO PROFESSIONALE",exp_SILP!$AD15="."),"A.3 ORIENTAMENTO PROFESSIONALE (CARCERE)", IF(AND(exp_SILP!$S15="A.4 CONSULENZA ORIENTATIVA",exp_SILP!$AD15="4.2"),"A.4 CONSULENZA ORIENTATIVA (CARCERE)", IF(AND(exp_SILP!$S15="A.4 CONSULENZA ORIENTATIVA",exp_SILP!$AD15="."),"A.4 CONSULENZA ORIENTATIVA (CARCERE)", IF(AND(exp_SILP!$S15="A.5 - LEP F1 - ACCOMPAGNAMENTO AL LAVORO",exp_SILP!$AD15="4.2"),"A.5 - LEP F1 - ACCOMPAGNAMENTO AL LAVORO (CARCERE)", IF(AND(exp_SILP!$S15="A.5 - LEP F1 - ACCOMPAGNAMENTO AL LAVORO",exp_SILP!$AD15="."),"A.5 - LEP F1 - ACCOMPAGNAMENTO AL LAVORO (CARCERE)", IF(AND(exp_SILP!$S15="A.5.2a - TUTORAGGIO TIROCINI",exp_SILP!$AD15="4.2"),"A.5.2a - TUTORAGGIO TIROCINI (CARCERE)", exp_SILP!$S15))))))) -> A4.10 - LEP E - ORIENTAMENTO SPECIALISTICO SKILL GAP ANALYSIS | C15: =CONCATENATE(VLOOKUP(exp_SILP!$B15,'DATI COMMESSE'!$A$2:$F$25,4,FALSE)," - ", VLOOKUP(exp_SILP!$B15,'DATI COMMESSE'!$A$2:$F$25,2,FALSE)," - ",VLOOKUP(exp_SILP!$B15,'DATI COMMESSE'!$A$2:$F$25,3,FALSE)) -> GOL - 22-02-5000 - 22-12-5003 | D15: =LEFT(exp_SILP!$R15,5) -> 12:30 | E15: =RIGHT(exp_SILP!$R15,5) -> 14:30 | F15: =IF(exp_SILP!$AG15>=60,exp_SILP!$AG15/60,exp_SILP!$AG15) -> 2 | G15: =VLOOKUP(exp_SILP!$Y15,'DATI CM'!$A$2:$F$28,2,FALSE) -> TRZCST69B41F952V | H15: =VLOOKUP(exp_SILP!$Y15,'DATI CM'!$A$2:$F$28,3,FALSE) | I15: =IF(A15>0,"N","N") -> N | J15: =VLOOKUP(exp_SILP!$Y15,'DATI CM'!$A$2:$F$28,4,FALSE) | K15: =VLOOKUP(exp_SILP!$B15,'DATI COMMESSE'!$A$2:$F$25,5,FALSE) -> 39.94 | L15: =IF(exp_SILP!$B15="A4.10 - LEP E - ORIENTAMENTO SPECIALISTICO SKILL GAP ANALYSIS - GRUPPO 3P",0,VLOOKUP(exp_SILP!$Y15,'DATI CM'!$A$2:$F$28,6,FALSE)) | M15: =IFERROR(VLOOKUP(exp_SILP!$B15,'DATI CM'!$H$2:$I$16,2,FALSE)*exp_SILP!$F15,0) -> 0 | N15: =VLOOKUP(exp_SILP!$B15,'DATI COMMESSE'!$A$2:$F$25,4,FALSE) -> GOL | O15: =VLOOKUP(exp_SILP!$B15,'DATI COMMESSE'!$A$2:$F$25,5,FALSE)*exp_SILP!$F15 -> 79.88 | P15: =IF(MID(exp_SILP!$W15,10,2)>"40","F","M") -> M | Q15: 01/03/2023 | R15: 12:30-14:30 | S15: A4.10 - LEP E - ORIENTAMENTO SPECIALISTICO SKILL GAP ANALYSIS | T15: Progetti per accreditati | V15: ELIA GIANLUCA | W15: LEIGLC70M01F952G | X15: 01/08/1970 | Y15: TERZERA CRISTINA | Z15: Erogato | AA15: INFORCOOP ECIPA PIEMONTE | AB15: Incontro MDL | AC15: INFORCOOP ECIPA PIEMONTE VIA UGO PORZIO GIOVANOLA 7 - NOVARA | AG15: 120 | AH15: 01/03/2023 | AI15: TRZCST69B41F952V | AJ15: =VLOOKUP(exp_SILP!$Y15,'DATI CM'!$A$2:$F$28,2,FALSE) -> TRZCST69B41F952V
A16: =IFERROR(VLOOKUP(exp_SILP!$W16,exp_utenti_P!D:D,1,FALSE),"_DA INSERIRE") -> SDRMLA83A50Z330A | B16: =IF(AND(exp_SILP!$S16="A.3 ORIENTAMENTO PROFESSIONALE",exp_SILP!$AD16="4.2"),"A.3 ORIENTAMENTO PROFESSIONALE (CARCERE)", IF(AND(exp_SILP!$S16="A.3 ORIENTAMENTO PROFESSIONALE",exp_SILP!$AD16="."),"A.3 ORIENTAMENTO PROFESSIONALE (CARCERE)", IF(AND(exp_SILP!$S16="A.4 CONSULENZA ORIENTATIVA",exp_SILP!$AD16="4.2"),"A.4 CONSULENZA ORIENTATIVA (CARCERE)", IF(AND(exp_SILP!$S16="A.4 CONSULENZA ORIENTATIVA",exp_SILP!$AD16="."),"A.4 CONSULENZA ORIENTATIVA (CARCERE)", IF(AND(exp_SILP!$S16="A.5 - LEP F1 - ACCOMPAGNAMENTO AL LAVORO",exp_SILP!$AD16="4.2"),"A.5 - LEP F1 - ACCOMPAGNAMENTO AL LAVORO (CARCERE)", IF(AND(exp_SILP!$S16="A.5 - LEP F1 - ACCOMPAGNAMENTO AL LAVORO",exp_SILP!$AD16="."),"A.5 - LEP F1 - ACCOMPAGNAMENTO AL LAVORO (CARCERE)", IF(AND(exp_SILP!$S16="A.5.2a - TUTORAGGIO TIROCINI",exp_SILP!$AD16="4.2"),"A.5.2a - TUTORAGGIO TIROCINI (CARCERE)", exp_SILP!$S16))))))) -> A4.10 - LEP E - ORIENTAMENTO SPECIALISTICO SKILL GAP ANALYSIS | C16: =CONCATENATE(VLOOKUP(exp_SILP!$B16,'DATI COMMESSE'!$A$2:$F$25,4,FALSE)," - ", VLOOKUP(exp_SILP!$B16,'DATI COMMESSE'!$A$2:$F$25,2,FALSE)," - ",VLOOKUP(exp_SILP!$B16,'DATI COMMESSE'!$A$2:$F$25,3,FALSE)) -> GOL - 22-02-5000 - 22-12-5003 | D16: =LEFT(exp_SILP!$R16,5) -> 14:00 | E16: =RIGHT(exp_SILP!$R16,5) -> 18:00 | F16: =IF(exp_SILP!$AG16>=60,exp_SILP!$AG16/60,exp_SILP!$AG16) -> 4 | G16: =VLOOKUP(exp_SILP!$Y16,'DATI CM'!$A$2:$F$28,2,FALSE) -> SPDPRZ67H55L219V | H16: =VLOOKUP(exp_SILP!$Y16,'DATI CM'!$A$2:$F$28,3,FALSE) -> A010 | I16: =IF(A16>0,"N","N") -> N | J16: =VLOOKUP(exp_SILP!$Y16,'DATI CM'!$A$2:$F$28,4,FALSE) -> TORINO | K16: =VLOOKUP(exp_SILP!$B16,'DATI COMMESSE'!$A$2:$F$25,5,FALSE) -> 39.94 | L16: =IF(exp_SILP!$B16="A4.10 - LEP E - ORIENTAMENTO SPECIALISTICO SKILL GAP ANALYSIS - GRUPPO 3P",0,VLOOKUP(exp_SILP!$Y16,'DATI CM'!$A$2:$F$28,6,FALSE)) | M16: =IFERROR(VLOOKUP(exp_SILP!$B16,'DATI CM'!$H$2:$I$16,2,FALSE)*exp_SILP!$F16,0) -> 0 | N16: =VLOOKUP(exp_SILP!$B16,'DATI COMMESSE'!$A$2:$F$25,4,FALSE) -> GOL | O16: =VLOOKUP(exp_SILP!$B16,'DATI COMMESSE'!$A$2:$F$25,5,FALSE)*exp_SILP!$F16 -> 159.76 | P16: =IF(MID(exp_SILP!$W16,10,2)>"40","F","M") -> F | Q16: 01/03/2023 | R16: 14:00-18:00 | S16: A4.10 - LEP E - ORIENTAMENTO SPECIALISTICO SKILL GAP ANALYSIS | T16: Progetti per accreditati | V16: SADRI AMAL | W16: SDRMLA83A50Z330A | X16: 10/01/1983 | Y16: SPADARO PATRIZIA | Z16: Erogato | AA16: INFORCOOP ECIPA PIEMONTE | AB16: Incontro MDL | AC16: INFORCOOP ECIPA PIEMONTE VIA TREVISO 12 - TORINO | AG16: 240 | AH16: 01/03/2023 | AI16: SPDPRZ67H55L219V | AJ16: =VLOOKUP(exp_SILP!$Y16,'DATI CM'!$A$2:$F$28,2,FALSE) -> SPDPRZ67H55L219V
A17: =IFERROR(VLOOKUP(exp_SILP!$W17,exp_utenti_P!D:D,1,FALSE),"_DA INSERIRE") -> BNCDLM80L07L219L | B17: =IF(AND(exp_SILP!$S17="A.3 ORIENTAMENTO PROFESSIONALE",exp_SILP!$AD17="4.2"),"A.3 ORIENTAMENTO PROFESSIONALE (CARCERE)", IF(AND(exp_SILP!$S17="A.3 ORIENTAMENTO PROFESSIONALE",exp_SILP!$AD17="."),"A.3 ORIENTAMENTO PROFESSIONALE (CARCERE)", IF(AND(exp_SILP!$S17="A.4 CONSULENZA ORIENTATIVA",exp_SILP!$AD17="4.2"),"A.4 CONSULENZA ORIENTATIVA (CARCERE)", IF(AND(exp_SILP!$S17="A.4 CONSULENZA ORIENTATIVA",exp_SILP!$AD17="."),"A.4 CONSULENZA ORIENTATIVA (CARCERE)", IF(AND(exp_SILP!$S17="A.5 - LEP F1 - ACCOMPAGNAMENTO AL LAVORO",exp_SILP!$AD17="4.2"),"A.5 - LEP F1 - ACCOMPAGNAMENTO AL LAVORO (CARCERE)", IF(AND(exp_SILP!$S17="A.5 - LEP F1 - ACCOMPAGNAMENTO AL LAVORO",exp_SILP!$AD17="."),"A.5 - LEP F1 - ACCOMPAGNAMENTO AL LAVORO (CARCERE)", IF(AND(exp_SILP!$S17="A.5.2a - TUTORAGGIO TIROCINI",exp_SILP!$AD17="4.2"),"A.5.2a - TUTORAGGIO TIROCINI (CARCERE)", exp_SILP!$S17))))))) -> A.5 - LEP F1 - ACCOMPAGNAMENTO AL LAVORO | C17: =CONCATENATE(VLOOKUP(exp_SILP!$B17,'DATI COMMESSE'!$A$2:$F$25,4,FALSE)," - ", VLOOKUP(exp_SILP!$B17,'DATI COMMESSE'!$A$2:$F$25,2,FALSE)," - ",VLOOKUP(exp_SILP!$B17,'DATI COMMESSE'!$A$2:$F$25,3,FALSE)) -> GOL - 22-02-5000 - 22-12-5003 | D17: =LEFT(exp_SILP!$R17,5) -> 10:00 | E17: =RIGHT(exp_SILP!$R17,5) -> 11:00 | F17: =IF(exp_SILP!$AG17>=60,exp_SILP!$AG17/60,exp_SILP!$AG17) -> 1 | G17: =VLOOKUP(exp_SILP!$Y17,'DATI CM'!$A$2:$F$28,2,FALSE) -> DNRSMN97E58L219U | H17: =VLOOKUP(exp_SILP!$Y17,'DATI CM'!$A$2:$F$28,3,FALSE) | I17: =IF(A17>0,"N","N") -> N | J17: =VLOOKUP(exp_SILP!$Y17,'DATI CM'!$A$2:$F$28,4,FALSE) | K17: =VLOOKUP(exp_SILP!$B17,'DATI COMMESSE'!$A$2:$F$25,5,FALSE) -> 39.94 | L17: =IF(exp_SILP!$B17="A4.10 - LEP E - ORIENTAMENTO SPECIALISTICO SKILL GAP ANALYSIS - GRUPPO 3P",0,VLOOKUP(exp_SILP!$Y17,'DATI CM'!$A$2:$F$28,6,FALSE)) | M17: =IFERROR(VLOOKUP(exp_SILP!$B17,'DATI CM'!$H$2:$I$16,2,FALSE)*exp_SILP!$F17,0) -> 0 | N17: =VLOOKUP(exp_SILP!$B17,'DATI COMMESSE'!$A$2:$F$25,4,FALSE) -> GOL | O17: =VLOOKUP(exp_SILP!$B17,'DATI COMMESSE'!$A$2:$F$25,5,FALSE)*exp_SILP!$F17 -> 39.94 | P17: =IF(MID(exp_SILP!$W17,10,2)>"40","F","M") -> M | Q17: 01/06/2023 | R17: 10:00-11:00 | S17: A.5 - LEP F1 - ACCOMPAGNAMENTO AL LAVORO | T17: Progetti per accreditati | V17: BIANCO DANIELE MARCO | W17: BNCDLM80L07L219L | X17: 07/07/1980 | Y17: DENARO SIMONA | Z17: Erogato | AA17: INFORCOOP ECIPA PIEMONTE | AB17: Incontro MDL | AC17: INFORCOOP ECIPA PIEMONTE VIA TREVISO 12 - TORINO | AG17: 60 | AH17: 01/06/2023 | AI17: DNRSMN97E58L219U | AJ17: =VLOOKUP(exp_SILP!$Y17,'DATI CM'!$A$2:$F$28,2,FALSE) -> DNRSMN97E58L219U
A18: =IFERROR(VLOOKUP(exp_SILP!$W18,exp_utenti_P!D:D,1,FALSE),"_DA INSERIRE") -> BLSRRT80A25L219K | B18: =IF(AND(exp_SILP!$S18="A.3 ORIENTAMENTO PROFESSIONALE",exp_SILP!$AD18="4.2"),"A.3 ORIENTAMENTO PROFESSIONALE (CARCERE)", IF(AND(exp_SILP!$S18="A.3 ORIENTAMENTO PROFESSIONALE",exp_SILP!$AD18="."),"A.3 ORIENTAMENTO PROFESSIONALE (CARCERE)", IF(AND(exp_SILP!$S18="A.4 CONSULENZA ORIENTATIVA",exp_SILP!$AD18="4.2"),"A.4 CONSULENZA ORIENTATIVA (CARCERE)", IF(AND(exp_SILP!$S18="A.4 CONSULENZA ORIENTATIVA",exp_SILP!$AD18="."),"A.4 CONSULENZA ORIENTATIVA (CARCERE)", IF(AND(exp_SILP!$S18="A.5 - LEP F1 - ACCOMPAGNAMENTO AL LAVORO",exp_SILP!$AD18="4.2"),"A.5 - LEP F1 - ACCOMPAGNAMENTO AL LAVORO (CARCERE)", IF(AND(exp_SILP!$S18="A.5 - LEP F1 - ACCOMPAGNAMENTO AL LAVORO",exp_SILP!$AD18="."),"A.5 - LEP F1 - ACCOMPAGNAMENTO AL LAVORO (CARCERE)", IF(AND(exp_SILP!$S18="A.5.2a - TUTORAGGIO TIROCINI",exp_SILP!$AD18="4.2"),"A.5.2a - TUTORAGGIO TIROCINI (CARCERE)", exp_SILP!$S18))))))) -> A.5 - LEP F1 - ACCOMPAGNAMENTO AL LAVORO | C18: =CONCATENATE(VLOOKUP(exp_SILP!$B18,'DATI COMMESSE'!$A$2:$F$25,4,FALSE)," - ", VLOOKUP(exp_SILP!$B18,'DATI COMMESSE'!$A$2:$F$25,2,FALSE)," - ",VLOOKUP(exp_SILP!$B18,'DATI COMMESSE'!$A$2:$F$25,3,FALSE)) -> GOL - 22-02-5000 - 22-12-5003 | D18: =LEFT(exp_SILP!$R18,5) -> 15:00 | E18: =RIGHT(exp_SILP!$R18,5) -> 17:00 | F18: =IF(exp_SILP!$AG18>=60,exp_SILP!$AG18/60,exp_SILP!$AG18) -> 2 | G18: =VLOOKUP(exp_SILP!$Y18,'DATI CM'!$A$2:$F$28,2,FALSE) -> DNRSMN97E58L219U | H18: =VLOOKUP(exp_SILP!$Y18,'DATI CM'!$A$2:$F$28,3,FALSE) | I18: =IF(A18>0,"N","N") -> N | J18: =VLOOKUP(exp_SILP!$Y18,'DATI CM'!$A$2:$F$28,4,FALSE) | K18: =VLOOKUP(exp_SILP!$B18,'DATI COMMESSE'!$A$2:$F$25,5,FALSE) -> 39.94 | L18: =IF(exp_SILP!$B18="A4.10 - LEP E - ORIENTAMENTO SPECIALISTICO SKILL GAP ANALYSIS - GRUPPO 3P",0,VLOOKUP(exp_SILP!$Y18,'DATI CM'!$A$2:$F$28,6,FALSE)) | M18: =IFERROR(VLOOKUP(exp_SILP!$B18,'DATI CM'!$H$2:$I$16,2,FALSE)*exp_SILP!$F18,0) -> 0 | N18: =VLOOKUP(exp_SILP!$B18,'DATI COMMESSE'!$A$2:$F$25,4,FALSE) -> GOL | O18: =VLOOKUP(exp_SILP!$B18,'DATI COMMESSE'!$A$2:$F$25,5,FALSE)*exp_SILP!$F18 -> 79.88 | P18: =IF(MID(exp_SILP!$W18,10,2)>"40","F","M") -> M | Q18: 01/06/2023 | R18: 15:00-17:00 | S18: A.5 - LEP F1 - ACCOMPAGNAMENTO AL LAVORO | T18: Progetti per accreditati | V18: BELSITO ROBERTO | W18: BLSRRT80A25L219K | X18: 25/01/1980 | Y18: DENARO SIMONA | Z18: Erogato | AA18: INFORCOOP ECIPA PIEMONTE | AB18: Incontro MDL | AC18: INFORCOOP ECIPA PIEMONTE VIA TREVISO 12 - TORINO | AG18: 120 | AH18: 01/06/2023 | AI18: DNRSMN97E58L219U | AJ18: =VLOOKUP(exp_SILP!$Y18,'DATI CM'!$A$2:$F$28,2,FALSE) -> DNRSMN97E58L219U
A19: =IFERROR(VLOOKUP(exp_SILP!$W19,exp_utenti_P!D:D,1,FALSE),"_DA INSERIRE") -> DRDZRC92C41L219G | B19: =IF(AND(exp_SILP!$S19="A.3 ORIENTAMENTO PROFESSIONALE",exp_SILP!$AD19="4.2"),"A.3 ORIENTAMENTO PROFESSIONALE (CARCERE)", IF(AND(exp_SILP!$S19="A.3 ORIENTAMENTO PROFESSIONALE",exp_SILP!$AD19="."),"A.3 ORIENTAMENTO PROFESSIONALE (CARCERE)", IF(AND(exp_SILP!$S19="A.4 CONSULENZA ORIENTATIVA",exp_SILP!$AD19="4.2"),"A.4 CONSULENZA ORIENTATIVA (CARCERE)", IF(AND(exp_SILP!$S19="A.4 CONSULENZA ORIENTATIVA",exp_SILP!$AD19="."),"A.4 CONSULENZA ORIENTATIVA (CARCERE)", IF(AND(exp_SILP!$S19="A.5 - LEP F1 - ACCOMPAGNAMENTO AL LAVORO",exp_SILP!$AD19="4.2"),"A.5 - LEP F1 - ACCOMPAGNAMENTO AL LAVORO (CARCERE)", IF(AND(exp_SILP!$S19="A.5 - LEP F1 - ACCOMPAGNAMENTO AL LAVORO",exp_SILP!$AD19="."),"A.5 - LEP F1 - ACCOMPAGNAMENTO AL LAVORO (CARCERE)", IF(AND(exp_SILP!$S19="A.5.2a - TUTORAGGIO TIROCINI",exp_SILP!$AD19="4.2"),"A.5.2a - TUTORAGGIO TIROCINI (CARCERE)", exp_SILP!$S19))))))) -> A.5 - LEP F1 - ACCOMPAGNAMENTO AL LAVORO | C19: =CONCATENATE(VLOOKUP(exp_SILP!$B19,'DATI COMMESSE'!$A$2:$F$25,4,FALSE)," - ", VLOOKUP(exp_SILP!$B19,'DATI COMMESSE'!$A$2:$F$25,2,FALSE)," - ",VLOOKUP(exp_SILP!$B19,'DATI COMMESSE'!$A$2:$F$25,3,FALSE)) -> GOL - 22-02-5000 - 22-12-5003 | D19: =LEFT(exp_SILP!$R19,5) -> 16:00 | E19: =RIGHT(exp_SILP!$R19,5) -> 18:00 | F19: =IF(exp_SILP!$AG19>=60,exp_SILP!$AG19/60,exp_SILP!$AG19) -> 2 | G19: =VLOOKUP(exp_SILP!$Y19,'DATI CM'!$A$2:$F$28,2,FALSE) -> SPDPRZ67H55L219V | H19: =VLOOKUP(exp_SILP!$Y19,'DATI CM'!$A$2:$F$28,3,FALSE) -> A010 | I19: =IF(A19>0,"N","N") -> N | J19: =VLOOKUP(exp_SILP!$Y19,'DATI CM'!$A$2:$F$28,4,FALSE) -> TORINO | K19: =VLOOKUP(exp_SILP!$B19,'DATI COMMESSE'!$A$2:$F$25,5,FALSE) -> 39.94 | L19: =IF(exp_SILP!$B19="A4.10 - LEP E - ORIENTAMENTO SPECIALISTICO SKILL GAP ANALYSIS - GRUPPO 3P",0,VLOOKUP(exp_SILP!$Y19,'DATI CM'!$A$2:$F$28,6,FALSE)) | M19: =IFERROR(VLOOKUP(exp_SILP!$B19,'DATI CM'!$H$2:$I$16,2,FALSE)*exp_SILP!$F19,0) -> 0 | N19: =VLOOKUP(exp_SILP!$B19,'DATI COMMESSE'!$A$2:$F$25,4,FALSE) -> GOL | O19: =VLOOKUP(exp_SILP!$B19,'DATI COMMESSE'!$A$2:$F$25,5,FALSE)*exp_SILP!$F19 -> 79.88 | P19: =IF(MID(exp_SILP!$W19,10,2)>"40","F","M") -> F | Q19: 01/06/2023 | R19: 16:00-18:00 | S19: A.5 - LEP F1 - ACCOMPAGNAMENTO AL LAVORO | T19: Progetti per accreditati | V19: DORDEVIC ZORICA | W19: DRDZRC92C41L219G | X19: 01/03/1992 | Y19: SPADARO PATRIZIA | Z19: Erogato | AA19: INFORCOOP ECIPA PIEMONTE | AB19: Incontro MDL | AC19: INFORCOOP ECIPA PIEMONTE VIA TREVISO 12 - TORINO | AG19: 120 | AH19: 01/06/2023 | AI19: SPDPRZ67H55L219V | AJ19: =VLOOKUP(exp_SILP!$Y19,'DATI CM'!$A$2:$F$28,2,FALSE) -> SPDPRZ67H55L219V
A20: =IFERROR(VLOOKUP(exp_SILP!$W20,exp_utenti_P!D:D,1,FALSE),"_DA INSERIRE") -> RSSDRH73A55C351F | B20: =IF(AND(exp_SILP!$S20="A.3 ORIENTAMENTO PROFESSIONALE",exp_SILP!$AD20="4.2"),"A.3 ORIENTAMENTO PROFESSIONALE (CARCERE)", IF(AND(exp_SILP!$S20="A.3 ORIENTAMENTO PROFESSIONALE",exp_SILP!$AD20="."),"A.3 ORIENTAMENTO PROFESSIONALE (CARCERE)", IF(AND(exp_SILP!$S20="A.4 CONSULENZA ORIENTATIVA",exp_SILP!$AD20="4.2"),"A.4 CONSULENZA ORIENTATIVA (CARCERE)", IF(AND(exp_SILP!$S20="A.4 CONSULENZA ORIENTATIVA",exp_SILP!$AD20="."),"A.4 CONSULENZA ORIENTATIVA (CARCERE)", IF(AND(exp_SILP!$S20="A.5 - LEP F1 - ACCOMPAGNAMENTO AL LAVORO",exp_SILP!$AD20="4.2"),"A.5 - LEP F1 - ACCOMPAGNAMENTO AL LAVORO (CARCERE)", IF(AND(exp_SILP!$S20="A.5 - LEP F1 - ACCOMPAGNAMENTO AL LAVORO",exp_SILP!$AD20="."),"A.5 - LEP F1 - ACCOMPAGNAMENTO AL LAVORO (CARCERE)", IF(AND(exp_SILP!$S20="A.5.2a - TUTORAGGIO TIROCINI",exp_SILP!$AD20="4.2"),"A.5.2a - TUTORAGGIO TIROCINI (CARCERE)", exp_SILP!$S20))))))) -> A.5 - LEP F1 - ACCOMPAGNAMENTO AL LAVORO | C20: =CONCATENATE(VLOOKUP(exp_SILP!$B20,'DATI COMMESSE'!$A$2:$F$25,4,FALSE)," - ", VLOOKUP(exp_SILP!$B20,'DATI COMMESSE'!$A$2:$F$25,2,FALSE)," - ",VLOOKUP(exp_SILP!$B20,'DATI COMMESSE'!$A$2:$F$25,3,FALSE)) -> GOL - 22-02-5000 - 22-12-5003 | D20: =LEFT(exp_SILP!$R20,5) -> 16:00 | E20: =RIGHT(exp_SILP!$R20,5) -> 17:00 | F20: =IF(exp_SILP!$AG20>=60,exp_SILP!$AG20/60,exp_SILP!$AG20) -> 1 | G20: =VLOOKUP(exp_SILP!$Y20,'DATI CM'!$A$2:$F$28,2,FALSE) -> MNRCLD73B46G674U | H20: =VLOOKUP(exp_SILP!$Y20,'DATI CM'!$A$2:$F$28,3,FALSE) -> A011 | I20: =IF(A20>0,"N","N") -> N | J20: =VLOOKUP(exp_SILP!$Y20,'DATI CM'!$A$2:$F$28,4,FALSE) -> TORINO | K20: =VLOOKUP(exp_SILP!$B20,'DATI COMMESSE'!$A$2:$F$25,5,FALSE) -> 39.94 | L20: =IF(exp_SILP!$B20="A4.10 - LEP E - ORIENTAMENTO SPECIALISTICO SKILL GAP ANALYSIS - GRUPPO 3P",0,VLOOKUP(exp_SILP!$Y20,'DATI CM'!$A$2:$F$28,6,FALSE)) -> 25 | M20: =IFERROR(VLOOKUP(exp_SILP!$B20,'DATI CM'!$H$2:$I$16,2,FALSE)*exp_SILP!$F20,0) -> 0 | N20: =VLOOKUP(exp_SILP!$B20,'DATI COMMESSE'!$A$2:$F$25,4,FALSE) -> GOL | O20: =VLOOKUP(exp_SILP!$B20,'DATI COMMESSE'!$A$2:$F$25,5,FALSE)*exp_SILP!$F20 -> 39.94 | P20: =IF(MID(exp_SILP!$W20,10,2)>"40","F","M") -> F | Q20: 01/06/2023 | R20: 16:00-17:00 | S20: A.5 - LEP F1 - ACCOMPAGNAMENTO AL LAVORO | T20: Progetti per accreditati | V20: ROSSI DEBORAH | W20: RSSDRH73A55C351F | X20: 15/01/1973 | Y20: MAINERO CLAUDIA | Z20: Erogato | AA20: INFORCOOP ECIPA PIEMONTE | AB20: Incontro MDL | AC20: INFORCOOP ECIPA PIEMONTE VIA TREVISO 12 - TORINO | AF20: B.O. | AG20: 60 | AH20: 07/06/2023 | AI20: MNRCLD73B46G674U | AJ20: =VLOOKUP(exp_SILP!$Y20,'DATI CM'!$A$2:$F$28,2,FALSE) -> MNRCLD73B46G674U
A21: =IFERROR(VLOOKUP(exp_SILP!$W21,exp_utenti_P!D:D,1,FALSE),"_DA INSERIRE") -> TTNSFN74L68L219D | B21: =IF(AND(exp_SILP!$S21="A.3 ORIENTAMENTO PROFESSIONALE",exp_SILP!$AD21="4.2"),"A.3 ORIENTAMENTO PROFESSIONALE (CARCERE)", IF(AND(exp_SILP!$S21="A.3 ORIENTAMENTO PROFESSIONALE",exp_SILP!$AD21="."),"A.3 ORIENTAMENTO PROFESSIONALE (CARCERE)", IF(AND(exp_SILP!$S21="A.4 CONSULENZA ORIENTATIVA",exp_SILP!$AD21="4.2"),"A.4 CONSULENZA ORIENTATIVA (CARCERE)", IF(AND(exp_SILP!$S21="A.4 CONSULENZA ORIENTATIVA",exp_SILP!$AD21="."),"A.4 CONSULENZA ORIENTATIVA (CARCERE)", IF(AND(exp_SILP!$S21="A.5 - LEP F1 - ACCOMPAGNAMENTO AL LAVORO",exp_SILP!$AD21="4.2"),"A.5 - LEP F1 - ACCOMPAGNAMENTO AL LAVORO (CARCERE)", IF(AND(exp_SILP!$S21="A.5 - LEP F1 - ACCOMPAGNAMENTO AL LAVORO",exp_SILP!$AD21="."),"A.5 - LEP F1 - ACCOMPAGNAMENTO AL LAVORO (CARCERE)", IF(AND(exp_SILP!$S21="A.5.2a - TUTORAGGIO TIROCINI",exp_SILP!$AD21="4.2"),"A.5.2a - TUTORAGGIO TIROCINI (CARCERE)", exp_SILP!$S21))))))) -> A.5.1 ATTIVAZIONE E RICERCA OPPORTUNITA' (1-C) | C21: =CONCATENATE(VLOOKUP(exp_SILP!$B21,'DATI COMMESSE'!$A$2:$F$25,4,FALSE)," - ", VLOOKUP(exp_SILP!$B21,'DATI COMMESSE'!$A$2:$F$25,2,FALSE)," - ",VLOOKUP(exp_SILP!$B21,'DATI COMMESSE'!$A$2:$F$25,3,FALSE)) -> FRD - 22-02-5000 - 22-12-5002 | D21: =LEFT(exp_SILP!$R21,5) -> 13:00 | E21: =RIGHT(exp_SILP!$R21,5) -> 14:00 | F21: =IF(exp_SILP!$AG21>=60,exp_SILP!$AG21/60,exp_SILP!$AG21) -> 1 | G21: =VLOOKUP(exp_SILP!$Y21,'DATI CM'!$A$2:$F$28,2,FALSE) -> MNRCLD73B46G674U | H21: =VLOOKUP(exp_SILP!$Y21,'DATI CM'!$A$2:$F$28,3,FALSE) -> A011 | I21: =IF(A21>0,"N","N") -> N | J21: =VLOOKUP(exp_SILP!$Y21,'DATI CM'!$A$2:$F$28,4,FALSE) -> TORINO | K21: =VLOOKUP(exp_SILP!$B21,'DATI COMMESSE'!$A$2:$F$25,5,FALSE) -> 35.5 | L21: =IF(exp_SILP!$B21="A4.10 - LEP E - ORIENTAMENTO SPECIALISTICO SKILL GAP ANALYSIS - GRUPPO 3P",0,VLOOKUP(exp_SILP!$Y21,'DATI CM'!$A$2:$F$28,6,FALSE)) -> 25 | M21: =IFERROR(VLOOKUP(exp_SILP!$B21,'DATI CM'!$H$2:$I$16,2,FALSE)*exp_SILP!$F21,0) -> 0 | N21: =VLOOKUP(exp_SILP!$B21,'DATI COMMESSE'!$A$2:$F$25,4,FALSE) -> FRD | O21: =VLOOKUP(exp_SILP!$B21,'DATI COMMESSE'!$A$2:$F$25,5,FALSE)*exp_SILP!$F21 -> 35.5 | P21: =IF(MID(exp_SILP!$W21,10,2)>"40","F","M") -> F | Q21: 01/06/2023 | R21: 13:00-14:00 | S21: A.5.1 ATTIVAZIONE E RICERCA OPPORTUNITA' (1-C) | T21: Progetti per accreditati | V21: TITONE STEFANIA | W21: TTNSFN74L68L219D | X21: 28/07/1974 | Y21: MAINERO CLAUDIA | Z21: Erogato | AA21: INFORCOOP ECIPA PIEMONTE | AB21: Incontro MDL | AC21: INFORCOOP ECIPA PIEMONTE VIA TREVISO 12 - TORINO | AF21: B.O. | AG21: 60 | AH21: 07/06/2023 | AI21: MNRCLD73B46G674U | AJ21: =VLOOKUP(exp_SILP!$Y21,'DATI CM'!$A$2:$F$28,2,FALSE) -> MNRCLD73B46G674U
A22: =IFERROR(VLOOKUP(exp_SILP!$W22,exp_utenti_P!D:D,1,FALSE),"_DA INSERIRE") -> TTNSFN74L68L219D | B22: =IF(AND(exp_SILP!$S22="A.3 ORIENTAMENTO PROFESSIONALE",exp_SILP!$AD22="4.2"),"A.3 ORIENTAMENTO PROFESSIONALE (CARCERE)", IF(AND(exp_SILP!$S22="A.3 ORIENTAMENTO PROFESSIONALE",exp_SILP!$AD22="."),"A.3 ORIENTAMENTO PROFESSIONALE (CARCERE)", IF(AND(exp_SILP!$S22="A.4 CONSULENZA ORIENTATIVA",exp_SILP!$AD22="4.2"),"A.4 CONSULENZA ORIENTATIVA (CARCERE)", IF(AND(exp_SILP!$S22="A.4 CONSULENZA ORIENTATIVA",exp_SILP!$AD22="."),"A.4 CONSULENZA ORIENTATIVA (CARCERE)", IF(AND(exp_SILP!$S22="A.5 - LEP F1 - ACCOMPAGNAMENTO AL LAVORO",exp_SILP!$AD22="4.2"),"A.5 - LEP F1 - ACCOMPAGNAMENTO AL LAVORO (CARCERE)", IF(AND(exp_SILP!$S22="A.5 - LEP F1 - ACCOMPAGNAMENTO AL LAVORO",exp_SILP!$AD22="."),"A.5 - LEP F1 - ACCOMPAGNAMENTO AL LAVORO (CARCERE)", IF(AND(exp_SILP!$S22="A.5.2a - TUTORAGGIO TIROCINI",exp_SILP!$AD22="4.2"),"A.5.2a - TUTORAGGIO TIROCINI (CARCERE)", exp_SILP!$S22))))))) -> A.5.1 ATTIVAZIONE E RICERCA OPPORTUNITA' (1-C) | C22: =CONCATENATE(VLOOKUP(exp_SILP!$B22,'DATI COMMESSE'!$A$2:$F$25,4,FALSE)," - ", VLOOKUP(exp_SILP!$B22,'DATI COMMESSE'!$A$2:$F$25,2,FALSE)," - ",VLOOKUP(exp_SILP!$B22,'DATI COMMESSE'!$A$2:$F$25,3,FALSE)) -> FRD - 22-02-5000 - 22-12-5002 | D22: =LEFT(exp_SILP!$R22,5) -> 10:00 | E22: =RIGHT(exp_SILP!$R22,5) -> 13:00 | F22: =IF(exp_SILP!$AG22>=60,exp_SILP!$AG22/60,exp_SILP!$AG22) -> 3 | G22: =VLOOKUP(exp_SILP!$Y22,'DATI CM'!$A$2:$F$28,2,FALSE) -> MNRCLD73B46G674U | H22: =VLOOKUP(exp_SILP!$Y22,'DATI CM'!$A$2:$F$28,3,FALSE) -> A011 | I22: =IF(A22>0,"N","N") -> N | J22: =VLOOKUP(exp_SILP!$Y22,'DATI CM'!$A$2:$F$28,4,FALSE) -> TORINO | K22: =VLOOKUP(exp_SILP!$B22,'DATI COMMESSE'!$A$2:$F$25,5,FALSE) -> 35.5 | L22: =IF(exp_SILP!$B22="A4.10 - LEP E - ORIENTAMENTO SPECIALISTICO SKILL GAP ANALYSIS - GRUPPO 3P",0,VLOOKUP(exp_SILP!$Y22,'DATI CM'!$A$2:$F$28,6,FALSE)) -> 25 | M22: =IFERROR(VLOOKUP(exp_SILP!$B22,'DATI CM'!$H$2:$I$16,2,FALSE)*exp_SILP!$F22,0) -> 0 | N22: =VLOOKUP(exp_SILP!$B22,'DATI COMMESSE'!$A$2:$F$25,4,FALSE) -> FRD | O22: =VLOOKUP(exp_SILP!$B22,'DATI COMMESSE'!$A$2:$F$25,5,FALSE)*exp_SILP!$F22 -> 106.5 | P22: =IF(MID(exp_SILP!$W22,10,2)>"40","F","M") -> F | Q22: 01/06/2023 | R22: 10:00-13:00 | S22: A.5.1 ATTIVAZIONE E RICERCA OPPORTUNITA' (1-C) | T22: Progetti per accreditati | V22: TITONE STEFANIA | W22: TTNSFN74L68L219D | X22: 28/07/1974 | Y22: MAINERO CLAUDIA | Z22: Erogato | AA22: INFORCOOP ECIPA PIEMONTE | AB22: Incontro MDLpresentato | AC22: INFORCOOP ECIPA PIEMONTE VIA TREVISO 12 - TORINO | AG22: 180 | AH22: 07/06/2023 | AI22: MNRCLD73B46G674U | AJ22: =VLOOKUP(exp_SILP!$Y22,'DATI CM'!$A$2:$F$28,2,FALSE) -> MNRCLD73B46G674U
A23: =IFERROR(VLOOKUP(exp_SILP!$W23,exp_utenti_P!D:D,1,FALSE),"_DA INSERIRE") -> MNFLNZ03E12C722P | B23: =IF(AND(exp_SILP!$S23="A.3 ORIENTAMENTO PROFESSIONALE",exp_SILP!$AD23="4.2"),"A.3 ORIENTAMENTO PROFESSIONALE (CARCERE)", IF(AND(exp_SILP!$S23="A.3 ORIENTAMENTO PROFESSIONALE",exp_SILP!$AD23="."),"A.3 ORIENTAMENTO PROFESSIONALE (CARCERE)", IF(AND(exp_SILP!$S23="A.4 CONSULENZA ORIENTATIVA",exp_SILP!$AD23="4.2"),"A.4 CONSULENZA ORIENTATIVA (CARCERE)", IF(AND(exp_SILP!$S23="A.4 CONSULENZA ORIENTATIVA",exp_SILP!$AD23="."),"A.4 CONSULENZA ORIENTATIVA (CARCERE)", IF(AND(exp_SILP!$S23="A.5 - LEP F1 - ACCOMPAGNAMENTO AL LAVORO",exp_SILP!$AD23="4.2"),"A.5 - LEP F1 - ACCOMPAGNAMENTO AL LAVORO (CARCERE)", IF(AND(exp_SILP!$S23="A.5 - LEP F1 - ACCOMPAGNAMENTO AL LAVORO",exp_SILP!$AD23="."),"A.5 - LEP F1 - ACCOMPAGNAMENTO AL LAVORO (CARCERE)", IF(AND(exp_SILP!$S23="A.5.2a - TUTORAGGIO TIROCINI",exp_SILP!$AD23="4.2"),"A.5.2a - TUTORAGGIO TIROCINI (CARCERE)", exp_SILP!$S23))))))) -> A.5.2a - TUTORAGGIO TIROCINI | C23: =CONCATENATE(VLOOKUP(exp_SILP!$B23,'DATI COMMESSE'!$A$2:$F$25,4,FALSE)," - ", VLOOKUP(exp_SILP!$B23,'DATI COMMESSE'!$A$2:$F$25,2,FALSE)," - ",VLOOKUP(exp_SILP!$B23,'DATI COMMESSE'!$A$2:$F$25,3,FALSE)) -> FRD - 22-02-5000 - 22-12-5002 | D23: =LEFT(exp_SILP!$R23,5) -> 08:00 | E23: =RIGHT(exp_SILP!$R23,5) -> 09:00 | F23: =IF(exp_SILP!$AG23>=60,exp_SILP!$AG23/60,exp_SILP!$AG23) -> 1 | G23: =VLOOKUP(exp_SILP!$Y23,'DATI CM'!$A$2:$F$28,2,FALSE) -> MNRCLD73B46G674U | H23: =VLOOKUP(exp_SILP!$Y23,'DATI CM'!$A$2:$F$28,3,FALSE) -> A011 | I23: =IF(A23>0,"N","N") -> N | J23: =VLOOKUP(exp_SILP!$Y23,'DATI CM'!$A$2:$F$28,4,FALSE) -> TORINO | K23: =VLOOKUP(exp_SILP!$B23,'DATI COMMESSE'!$A$2:$F$25,5,FALSE) -> 35.5 | L23: =IF(exp_SILP!$B23="A4.10 - LEP E - ORIENTAMENTO SPECIALISTICO SKILL GAP ANALYSIS - GRUPPO 3P",0,VLOOKUP(exp_SILP!$Y23,'DATI CM'!$A$2:$F$28,6,FALSE)) -> 25 | M23: =IFERROR(VLOOKUP(exp_SILP!$B23,'DATI CM'!$H$2:$I$16,2,FALSE)*exp_SILP!$F23,0) -> 0 | N23: =VLOOKUP(exp_SILP!$B23,'DATI COMMESSE'!$A$2:$F$25,4,FALSE) -> FRD | O23: =VLOOKUP(exp_SILP!$B23,'DATI COMMESSE'!$A$2:$F$25,5,FALSE)*exp_SILP!$F23 -> 35.5 | P23: =IF(MID(exp_SILP!$W23,10,2)>"40","F","M") -> M | Q23: 01/06/2023 | R23: 08:00-09:00 | S23: A.5.2a - TUTORAGGIO TIROCINI | T23: Progetti per accreditati | V23: MANFREDI LORENZO | W23: MNFLNZ03E12C722P | X23: 12/05/2003 | Y23: MAINERO CLAUDIA | Z23: Erogato | AA23: INFORCOOP ECIPA PIEMONTE | AB23: Incontro MDLpresentato | AC23: INFORCOOP ECIPA PIEMONTE VIA TREVISO 12 - TORINO | AD23: TUTORAGGIO IN AZIENDA | AG23: 60 | AH23: 07/06/2023 | AI23: MNRCLD73B46G674U | AJ23: =VLOOKUP(exp_SILP!$Y23,'DATI CM'!$A$2:$F$28,2,FALSE) -> MNRCLD73B46G674U
